Workbook
Name SegmentaciónDeDatos_DEPARTAMENTO: #N/A
Name SegmentaciónDeDatos_PROVINCIA: #N/A
Name SegmentaciónDeDatos_TIPO_DE_SUPERFICIE: #N/A

Sheet Tac_Moq
A1: IDENTIFICADOR | B1: N° CONVENIO | C1: DEPARTAMENTO | D1: PROVINCIA | E1: DISTRITO | F1: CÓDIGO DE RUTA | G1: DENOMINACION DE INTERVENCION | H1: LONGITUD TOTAL (km) | I1: TIPO DE SUPERFICIE | J1: COSTO (km/mes) | K1: PLAZO (dc) | L1: EJECUCIÓN S/ | M1: GG.OO S/ | N1: TOTAL S/ | O1: N° DE CONTRATO | P1: CONTRATISTA | Q1: PLAZO CONTRACTUAL (DC) | R1: F. INICIO MANTENIMIENTO | S1: F. TERMINO MANTENIMIENTO | T1: MONTO CONTRATADO | U1: GASTOS OPERATIVOS (S/) | V1: TOTAL (S/) | W1: PLAZO DE ADENDA (DC) | X1: F. INICIO MANTENIMIENTO | Y1: F. TERMINO MANTENIMIENTO | Z1: MONTO DE ADENDA | AA1: GASTOS OPERATIVOS (S/) | AB1: TOTAL (S/) | AC1: N° TRAMITE | AD1: 46112 | AE1: MANTENIMIENTO S/ | AF1: GASTOS OPERATIVOS S/ | AG1: TOTAL S/ | AH1: N° TRAMITE | AI1: 46142 | AJ1: MANTENIMIENTO S/ | AK1: GASTOS OPERATIVOS S/ | AL1: TOTAL S/ | AM1: N° TRAMITE | AN1: 46173 | AO1: MANTENIMIENTO S/ | AP1: GASTOS OPERATIVOS S/ | AQ1: TOTAL S/ | AR1: N° TRAMITE | AS1: 46203 | AT1: MANTENIMIENTO S/ | AU1: GASTOS OPERATIVOS S/ | AV1: TOTAL S/ | AW1: N° TRAMITE | AX1: 46234 | AY1: MANTENIMIENTO S/ | AZ1: GASTOS OPERATIVOS S/ | BA1: TOTAL S/ | BB1: N° TRAMITE | BC1: 46265 | BD1: MANTENIMIENTO S/ | BE1: GASTOS OPERATIVOS S/ | BF1: TOTAL S/ | BG1: N° TRAMITE | BH1: 46295 | BI1: MANTENIMIENTO S/ | BJ1: GASTOS OPERATIVOS S/ | BK1: TOTAL S/ | BL1: N° TRAMITE | BM1: 46326 | BN1: MANTENIMIENTO S/ | BO1: GASTOS OPERATIVOS S/ | BP1: TOTAL S/ | BQ1: N° TRAMITE | BR1: 46356 | BS1: MANTENIMIENTO S/ | BT1: GASTOS OPERATIVOS S/ | BU1: TOTAL S/ | BV1: N° TRAMITE | BW1: 46387 | BX1: MANTENIMIENTO S/ | BY1: GASTOS OPERATIVOS S/ | BZ1: TOTAL S/ | CA1: TOTAL DIAS EJECUTADOS | CB1: MANTENIMIENTO S/ | CC1: GASTOS OPERATIVOS S/ | CD1: TOTAL S/ | CE1: ERROR MANTENIMIENTO | CF1: ERROR GASTOS OPERATIVOS | CG1: AREA USUARIA | CH1: RESPONSABLE DE AREA USUARIA | CI1: CARGO | CJ1: TELEFONO AU | CK1: INSPECTOR | CL1: DOC. DESIGNACIÓN | CM1: FECHA DESIGNACIÓN | CN1: TELEFONO INSPECTOR | CO1: MONITOR | CP1: TELEFONO MONITOR
A2: 1 | B2: 236 | C2: MOQUEGUA | D2: ILO | E2: ALGARROBAL | F2: MO-609 | G2: LA PAMPA (KM 13+600) - EMP. PE-36 (KM 21+725) | H2: 8.125 | I2: AFIRMADO | J2: 735 | K2: 240 | L2: 47775 | M2: 4777 | N2: 52552 | Q2: =+$K2 -> 240 | S2: =IF(Q2+R2=0,"",Q2+R2-1) -> 239 | U2: =+ROUND(T2*0.1,2) -> 0 | V2: =+SUM(T2:U2) -> 0 | X2: =+$R2 -> 0 | Y2: =IF(W2>0,X2+W2-1,"") | AA2: =+ROUND(Z2*0.1,2) -> 0 | AB2: =+SUM(Z2:AA2) -> 0 | AD2: =MAX(0,MIN(IF($Y2<>"",$Y2,$S2),AD$1)-MAX($R2,EOMONTH(AD$1,-1)+1)+1) -> 0 | AE2: =ROUND(IF($Z2="",$T2,$Z2)*(AD2/IF($W2="",$Q2,$W2)),2) -> 0 | AF2: =+ROUND(AE2*0.1,2) -> 0 | AG2: =+SUM(AE2:AF2) -> 0 | AI2: =MAX(0,MIN(IF($Y2<>"",$Y2,$S2),AI$1)-MAX($R2,EOMONTH(AI$1,-1)+1)+1) -> 0 | AJ2: =ROUND(IF($Z2="",$T2,$Z2)*(AI2/IF($W2="",$Q2,$W2)),2) -> 0 | AK2: =+ROUND(AJ2*0.1,2) -> 0 | AL2: =+SUM(AJ2:AK2) -> 0 | AN2: =MAX(0,MIN(IF($Y2<>"",$Y2,$S2),AN$1)-MAX($R2,EOMONTH(AN$1,-1)+1)+1) -> 0 | AO2: =ROUND(IF($Z2="",$T2,$Z2)*(AN2/IF($W2="",$Q2,$W2)),2) -> 0 | AP2: =+ROUND(AO2*0.1,2) -> 0 | AQ2: =+SUM(AO2:AP2) -> 0 | AS2: =MAX(0,MIN(IF($Y2<>"",$Y2,$S2),AS$1)-MAX($R2,EOMONTH(AS$1,-1)+1)+1) -> 0 | AT2: =ROUND(IF($Z2="",$T2,$Z2)*(AS2/IF($W2="",$Q2,$W2)),2) -> 0 | AU2: =+ROUND(AT2*0.1,2) -> 0 | AV2: =+SUM(AT2:AU2) -> 0 | AX2: =MAX(0,MIN(IF($Y2<>"",$Y2,$S2),AX$1)-MAX($R2,EOMONTH(AX$1,-1)+1)+1) -> 0 | AY2: =ROUND(IF($Z2="",$T2,$Z2)*(AX2/IF($W2="",$Q2,$W2)),2) -> 0 | AZ2: =+ROUND(AY2*0.1,2) -> 0 | BA2: =+SUM(AY2:AZ2) -> 0 | BC2: =MAX(0,MIN(IF($Y2<>"",$Y2,$S2),BC$1)-MAX($R2,EOMONTH(BC$1,-1)+1)+1) -> 0 | BD2: =ROUND(IF($Z2="",$T2,$Z2)*(BC2/IF($W2="",$Q2,$W2)),2) -> 0 | BE2: =+ROUND(BD2*0.1,2) -> 0 | BF2: =+SUM(BD2:BE2) -> 0 | BH2: =MAX(0,MIN(IF($Y2<>"",$Y2,$S2),BH$1)-MAX($R2,EOMONTH(BH$1,-1)+1)+1) -> 0 | BI2: =ROUND(IF($Z2="",$T2,$Z2)*(BH2/IF($W2="",$Q2,$W2)),2) -> 0 | BJ2: =+ROUND(BI2*0.1,2) -> 0 | BK2: =+SUM(BI2:BJ2) -> 0 | BM2: =MAX(0,MIN(IF($Y2<>"",$Y2,$S2),BM$1)-MAX($R2,EOMONTH(BM$1,-1)+1)+1) -> 0 | BN2: =ROUND(IF($Z2="",$T2,$Z2)*(BM2/IF($W2="",$Q2,$W2)),2) -> 0 | BO2: =+ROUND(BN2*0.1,2) -> 0 | BP2: =+SUM(BN2:BO2) -> 0 | BR2: =MAX(0,MIN(IF($Y2<>"",$Y2,$S2),BR$1)-MAX($R2,EOMONTH(BR$1,-1)+1)+1) -> 0 | BS2: =ROUND(IF($Z2="",$T2,$Z2)*(BR2/IF($W2="",$Q2,$W2)),2) -> 0 | BT2: =+ROUND(BS2*0.1,2) -> 0 | BU2: =+SUM(BS2:BT2) -> 0 | BW2: =MAX(0,MIN(IF($Y2<>"",$Y2,$S2),BW$1)-MAX($R2,EOMONTH(BW$1,-1)+1)+1) -> 0 | BX2: =ROUND(IF($Z2="",$T2,$Z2)*(BW2/IF($W2="",$Q2,$W2)),2) -> 0 | BY2: =+ROUND(BX2*0.1,2) -> 0 | BZ2: =+SUM(BX2:BY2) -> 0 | CA2: =+AD2+AI2+AN2+AS2+AX2+BC2+BH2+BM2+BR2+BW2 -> 0 | CB2: =+AE2+AJ2+AO2+AT2+AY2+BD2+BI2+BN2+BS2+BX2 -> 0 | CC2: =+AF2+AK2+AP2+AU2+AZ2+BE2+BJ2+BO2+BT2+BY2 -> 0 | CD2: =+SUM(CB2:CC2) -> 0 | CE2: =ROUND(IF($Y2<>"",$Z2,$T2)-CB2,2) -> 0 | CF2: =ROUND(IF($Y2<>"",$AA2,$U2)-CC2,2) -> 0 | CG2: GERENCIA DE TRANSPORTE PUBLICO Y CIRCULACION VIAL | CH2: Pamela Aida Flores Laqui | CI2: Gerente | CJ2: 951 902 578
A3: 2 | B3: 236 | C3: MOQUEGUA | D3: ILO | E3: ALGARROBAL | F3: MO-610 | G3: LORETO (KM 0+280) - YARAL FLORIDA - PEDREGAL - BOCATOMA DE AGUA POTABLE (KM 06+593) | H3: 6.313 | I3: AFIRMADO | J3: 735 | K3: 240 | L3: 37120 | M3: 3712 | N3: 40832 | Q3: =+$K3 -> 240 | S3: =IF(Q3+R3=0,"",Q3+R3-1) -> 239 | U3: =+ROUND(T3*0.1,2) -> 0 | V3: =+SUM(T3:U3) -> 0 | X3: =+$R3 -> 0 | Y3: =IF(W3>0,X3+W3-1,"") | AA3: =+ROUND(Z3*0.1,2) -> 0 | AB3: =+SUM(Z3:AA3) -> 0 | AD3: =MAX(0,MIN(IF($Y3<>"",$Y3,$S3),AD$1)-MAX($R3,EOMONTH(AD$1,-1)+1)+1) -> 0 | AE3: =ROUND(IF($Z3="",$T3,$Z3)*(AD3/IF($W3="",$Q3,$W3)),2) -> 0 | AF3: =+ROUND(AE3*0.1,2) -> 0 | AG3: =+SUM(AE3:AF3) -> 0 | AI3: =MAX(0,MIN(IF($Y3<>"",$Y3,$S3),AI$1)-MAX($R3,EOMONTH(AI$1,-1)+1)+1) -> 0 | AJ3: =ROUND(IF($Z3="",$T3,$Z3)*(AI3/IF($W3="",$Q3,$W3)),2) -> 0 | AK3: =+ROUND(AJ3*0.1,2) -> 0 | AL3: =+SUM(AJ3:AK3) -> 0 | AN3: =MAX(0,MIN(IF($Y3<>"",$Y3,$S3),AN$1)-MAX($R3,EOMONTH(AN$1,-1)+1)+1) -> 0 | AO3: =ROUND(IF($Z3="",$T3,$Z3)*(AN3/IF($W3="",$Q3,$W3)),2) -> 0 | AP3: =+ROUND(AO3*0.1,2) -> 0 | AQ3: =+SUM(AO3:AP3) -> 0 | AS3: =MAX(0,MIN(IF($Y3<>"",$Y3,$S3),AS$1)-MAX($R3,EOMONTH(AS$1,-1)+1)+1) -> 0 | AT3: =ROUND(IF($Z3="",$T3,$Z3)*(AS3/IF($W3="",$Q3,$W3)),2) -> 0 | AU3: =+ROUND(AT3*0.1,2) -> 0 | AV3: =+SUM(AT3:AU3) -> 0 | AX3: =MAX(0,MIN(IF($Y3<>"",$Y3,$S3),AX$1)-MAX($R3,EOMONTH(AX$1,-1)+1)+1) -> 0 | AY3: =ROUND(IF($Z3="",$T3,$Z3)*(AX3/IF($W3="",$Q3,$W3)),2) -> 0 | AZ3: =+ROUND(AY3*0.1,2) -> 0 | BA3: =+SUM(AY3:AZ3) -> 0 | BC3: =MAX(0,MIN(IF($Y3<>"",$Y3,$S3),BC$1)-MAX($R3,EOMONTH(BC$1,-1)+1)+1) -> 0 | BD3: =ROUND(IF($Z3="",$T3,$Z3)*(BC3/IF($W3="",$Q3,$W3)),2) -> 0 | BE3: =+ROUND(BD3*0.1,2) -> 0 | BF3: =+SUM(BD3:BE3) -> 0 | BH3: =MAX(0,MIN(IF($Y3<>"",$Y3,$S3),BH$1)-MAX($R3,EOMONTH(BH$1,-1)+1)+1) -> 0 | BI3: =ROUND(IF($Z3="",$T3,$Z3)*(BH3/IF($W3="",$Q3,$W3)),2) -> 0 | BJ3: =+ROUND(BI3*0.1,2) -> 0 | BK3: =+SUM(BI3:BJ3) -> 0 | BM3: =MAX(0,MIN(IF($Y3<>"",$Y3,$S3),BM$1)-MAX($R3,EOMONTH(BM$1,-1)+1)+1) -> 0 | BN3: =ROUND(IF($Z3="",$T3,$Z3)*(BM3/IF($W3="",$Q3,$W3)),2) -> 0 | BO3: =+ROUND(BN3*0.1,2) -> 0 | BP3: =+SUM(BN3:BO3) -> 0 | BR3: =MAX(0,MIN(IF($Y3<>"",$Y3,$S3),BR$1)-MAX($R3,EOMONTH(BR$1,-1)+1)+1) -> 0 | BS3: =ROUND(IF($Z3="",$T3,$Z3)*(BR3/IF($W3="",$Q3,$W3)),2) -> 0 | BT3: =+ROUND(BS3*0.1,2) -> 0 | BU3: =+SUM(BS3:BT3) -> 0 | BW3: =MAX(0,MIN(IF($Y3<>"",$Y3,$S3),BW$1)-MAX($R3,EOMONTH(BW$1,-1)+1)+1) -> 0 | BX3: =ROUND(IF($Z3="",$T3,$Z3)*(BW3/IF($W3="",$Q3,$W3)),2) -> 0 | BY3: =+ROUND(BX3*0.1,2) -> 0 | BZ3: =+SUM(BX3:BY3) -> 0 | CA3: =+AD3+AI3+AN3+AS3+AX3+BC3+BH3+BM3+BR3+BW3 -> 0 | CB3: =+AE3+AJ3+AO3+AT3+AY3+BD3+BI3+BN3+BS3+BX3 -> 0 | CC3: =+AF3+AK3+AP3+AU3+AZ3+BE3+BJ3+BO3+BT3+BY3 -> 0 | CD3: =+SUM(CB3:CC3) -> 0 | CE3: =ROUND(IF($Y3<>"",$Z3,$T3)-CB3,2) -> 0 | CF3: =ROUND(IF($Y3<>"",$AA3,$U3)-CC3,2) -> 0 | CG3: GERENCIA DE TRANSPORTE PUBLICO Y CIRCULACION VIAL | CH3: Pamela Aida Flores Laqui | CI3: Gerente | CJ3: 951 902 578
A4: 3 | B4: 236 | C4: MOQUEGUA | D4: ILO | E4: ILO; ALGARROBAL | F4: MO-609 | G4: EMP. PE-1S D - EL ALGARROBAL - EL HUESITO - LA PAMPA (KM 13+600) | H4: 13.6 | I4: PAVIMENTADO | J4: 880 | K4: 240 | L4: 95744 | M4: 9574 | N4: 105318 | Q4: =+$K4 -> 240 | S4: =IF(Q4+R4=0,"",Q4+R4-1) -> 239 | U4: =+ROUND(T4*0.1,2) -> 0 | V4: =+SUM(T4:U4) -> 0 | X4: =+$R4 -> 0 | Y4: =IF(W4>0,X4+W4-1,"") | AA4: =+ROUND(Z4*0.1,2) -> 0 | AB4: =+SUM(Z4:AA4) -> 0 | AD4: =MAX(0,MIN(IF($Y4<>"",$Y4,$S4),AD$1)-MAX($R4,EOMONTH(AD$1,-1)+1)+1) -> 0 | AE4: =ROUND(IF($Z4="",$T4,$Z4)*(AD4/IF($W4="",$Q4,$W4)),2) -> 0 | AF4: =+ROUND(AE4*0.1,2) -> 0 | AG4: =+SUM(AE4:AF4) -> 0 | AI4: =MAX(0,MIN(IF($Y4<>"",$Y4,$S4),AI$1)-MAX($R4,EOMONTH(AI$1,-1)+1)+1) -> 0 | AJ4: =ROUND(IF($Z4="",$T4,$Z4)*(AI4/IF($W4="",$Q4,$W4)),2) -> 0 | AK4: =+ROUND(AJ4*0.1,2) -> 0 | AL4: =+SUM(AJ4:AK4) -> 0 | AN4: =MAX(0,MIN(IF($Y4<>"",$Y4,$S4),AN$1)-MAX($R4,EOMONTH(AN$1,-1)+1)+1) -> 0 | AO4: =ROUND(IF($Z4="",$T4,$Z4)*(AN4/IF($W4="",$Q4,$W4)),2) -> 0 | AP4: =+ROUND(AO4*0.1,2) -> 0 | AQ4: =+SUM(AO4:AP4) -> 0 | AS4: =MAX(0,MIN(IF($Y4<>"",$Y4,$S4),AS$1)-MAX($R4,EOMONTH(AS$1,-1)+1)+1) -> 0 | AT4: =ROUND(IF($Z4="",$T4,$Z4)*(AS4/IF($W4="",$Q4,$W4)),2) -> 0 | AU4: =+ROUND(AT4*0.1,2) -> 0 | AV4: =+SUM(AT4:AU4) -> 0 | AX4: =MAX(0,MIN(IF($Y4<>"",$Y4,$S4),AX$1)-MAX($R4,EOMONTH(AX$1,-1)+1)+1) -> 0 | AY4: =ROUND(IF($Z4="",$T4,$Z4)*(AX4/IF($W4="",$Q4,$W4)),2) -> 0 | AZ4: =+ROUND(AY4*0.1,2) -> 0 | BA4: =+SUM(AY4:AZ4) -> 0 | BC4: =MAX(0,MIN(IF($Y4<>"",$Y4,$S4),BC$1)-MAX($R4,EOMONTH(BC$1,-1)+1)+1) -> 0 | BD4: =ROUND(IF($Z4="",$T4,$Z4)*(BC4/IF($W4="",$Q4,$W4)),2) -> 0 | BE4: =+ROUND(BD4*0.1,2) -> 0 | BF4: =+SUM(BD4:BE4) -> 0 | BH4: =MAX(0,MIN(IF($Y4<>"",$Y4,$S4),BH$1)-MAX($R4,EOMONTH(BH$1,-1)+1)+1) -> 0 | BI4: =ROUND(IF($Z4="",$T4,$Z4)*(BH4/IF($W4="",$Q4,$W4)),2) -> 0 | BJ4: =+ROUND(BI4*0.1,2) -> 0 | BK4: =+SUM(BI4:BJ4) -> 0 | BM4: =MAX(0,MIN(IF($Y4<>"",$Y4,$S4),BM$1)-MAX($R4,EOMONTH(BM$1,-1)+1)+1) -> 0 | BN4: =ROUND(IF($Z4="",$T4,$Z4)*(BM4/IF($W4="",$Q4,$W4)),2) -> 0 | BO4: =+ROUND(BN4*0.1,2) -> 0 | BP4: =+SUM(BN4:BO4) -> 0 | BR4: =MAX(0,MIN(IF($Y4<>"",$Y4,$S4),BR$1)-MAX($R4,EOMONTH(BR$1,-1)+1)+1) -> 0 | BS4: =ROUND(IF($Z4="",$T4,$Z4)*(BR4/IF($W4="",$Q4,$W4)),2) -> 0 | BT4: =+ROUND(BS4*0.1,2) -> 0 | BU4: =+SUM(BS4:BT4) -> 0 | BW4: =MAX(0,MIN(IF($Y4<>"",$Y4,$S4),BW$1)-MAX($R4,EOMONTH(BW$1,-1)+1)+1) -> 0 | BX4: =ROUND(IF($Z4="",$T4,$Z4)*(BW4/IF($W4="",$Q4,$W4)),2) -> 0 | BY4: =+ROUND(BX4*0.1,2) -> 0 | BZ4: =+SUM(BX4:BY4) -> 0 | CA4: =+AD4+AI4+AN4+AS4+AX4+BC4+BH4+BM4+BR4+BW4 -> 0 | CB4: =+AE4+AJ4+AO4+AT4+AY4+BD4+BI4+BN4+BS4+BX4 -> 0 | CC4: =+AF4+AK4+AP4+AU4+AZ4+BE4+BJ4+BO4+BT4+BY4 -> 0 | CD4: =+SUM(CB4:CC4) -> 0 | CE4: =ROUND(IF($Y4<>"",$Z4,$T4)-CB4,2) -> 0 | CF4: =ROUND(IF($Y4<>"",$AA4,$U4)-CC4,2) -> 0 | CG4: GERENCIA DE TRANSPORTE PUBLICO Y CIRCULACION VIAL | CH4: Pamela Aida Flores Laqui | CI4: Gerente | CJ4: 951 902 578
A5: 4 | B5: 236 | C5: MOQUEGUA | D5: ILO | E5: ILO; ALGARROBAL | F5: MO-611 | G5: EMP. PE-36 - EMP. MO-609 (KM 05+389) | H5: 5.389 | I5: PAVIMENTADO | J5: 880 | K5: 240 | L5: 37939 | M5: 3793 | N5: 41732 | Q5: =+$K5 -> 240 | S5: =IF(Q5+R5=0,"",Q5+R5-1) -> 239 | U5: =+ROUND(T5*0.1,2) -> 0 | V5: =+SUM(T5:U5) -> 0 | X5: =+$R5 -> 0 | Y5: =IF(W5>0,X5+W5-1,"") | AA5: =+ROUND(Z5*0.1,2) -> 0 | AB5: =+SUM(Z5:AA5) -> 0 | AD5: =MAX(0,MIN(IF($Y5<>"",$Y5,$S5),AD$1)-MAX($R5,EOMONTH(AD$1,-1)+1)+1) -> 0 | AE5: =ROUND(IF($Z5="",$T5,$Z5)*(AD5/IF($W5="",$Q5,$W5)),2) -> 0 | AF5: =+ROUND(AE5*0.1,2) -> 0 | AG5: =+SUM(AE5:AF5) -> 0 | AI5: =MAX(0,MIN(IF($Y5<>"",$Y5,$S5),AI$1)-MAX($R5,EOMONTH(AI$1,-1)+1)+1) -> 0 | AJ5: =ROUND(IF($Z5="",$T5,$Z5)*(AI5/IF($W5="",$Q5,$W5)),2) -> 0 | AK5: =+ROUND(AJ5*0.1,2) -> 0 | AL5: =+SUM(AJ5:AK5) -> 0 | AN5: =MAX(0,MIN(IF($Y5<>"",$Y5,$S5),AN$1)-MAX($R5,EOMONTH(AN$1,-1)+1)+1) -> 0 | AO5: =ROUND(IF($Z5="",$T5,$Z5)*(AN5/IF($W5="",$Q5,$W5)),2) -> 0 | AP5: =+ROUND(AO5*0.1,2) -> 0 | AQ5: =+SUM(AO5:AP5) -> 0 | AS5: =MAX(0,MIN(IF($Y5<>"",$Y5,$S5),AS$1)-MAX($R5,EOMONTH(AS$1,-1)+1)+1) -> 0 | AT5: =ROUND(IF($Z5="",$T5,$Z5)*(AS5/IF($W5="",$Q5,$W5)),2) -> 0 | AU5: =+ROUND(AT5*0.1,2) -> 0 | AV5: =+SUM(AT5:AU5) -> 0 | AX5: =MAX(0,MIN(IF($Y5<>"",$Y5,$S5),AX$1)-MAX($R5,EOMONTH(AX$1,-1)+1)+1) -> 0 | AY5: =ROUND(IF($Z5="",$T5,$Z5)*(AX5/IF($W5="",$Q5,$W5)),2) -> 0 | AZ5: =+ROUND(AY5*0.1,2) -> 0 | BA5: =+SUM(AY5:AZ5) -> 0 | BC5: =MAX(0,MIN(IF($Y5<>"",$Y5,$S5),BC$1)-MAX($R5,EOMONTH(BC$1,-1)+1)+1) -> 0 | BD5: =ROUND(IF($Z5="",$T5,$Z5)*(BC5/IF($W5="",$Q5,$W5)),2) -> 0 | BE5: =+ROUND(BD5*0.1,2) -> 0 | BF5: =+SUM(BD5:BE5) -> 0 | BH5: =MAX(0,MIN(IF($Y5<>"",$Y5,$S5),BH$1)-MAX($R5,EOMONTH(BH$1,-1)+1)+1) -> 0 | BI5: =ROUND(IF($Z5="",$T5,$Z5)*(BH5/IF($W5="",$Q5,$W5)),2) -> 0 | BJ5: =+ROUND(BI5*0.1,2) -> 0 | BK5: =+SUM(BI5:BJ5) -> 0 | BM5: =MAX(0,MIN(IF($Y5<>"",$Y5,$S5),BM$1)-MAX($R5,EOMONTH(BM$1,-1)+1)+1) -> 0 | BN5: =ROUND(IF($Z5="",$T5,$Z5)*(BM5/IF($W5="",$Q5,$W5)),2) -> 0 | BO5: =+ROUND(BN5*0.1,2) -> 0 | BP5: =+SUM(BN5:BO5) -> 0 | BR5: =MAX(0,MIN(IF($Y5<>"",$Y5,$S5),BR$1)-MAX($R5,EOMONTH(BR$1,-1)+1)+1) -> 0 | BS5: =ROUND(IF($Z5="",$T5,$Z5)*(BR5/IF($W5="",$Q5,$W5)),2) -> 0 | BT5: =+ROUND(BS5*0.1,2) -> 0 | BU5: =+SUM(BS5:BT5) -> 0 | BW5: =MAX(0,MIN(IF($Y5<>"",$Y5,$S5),BW$1)-MAX($R5,EOMONTH(BW$1,-1)+1)+1) -> 0 | BX5: =ROUND(IF($Z5="",$T5,$Z5)*(BW5/IF($W5="",$Q5,$W5)),2) -> 0 | BY5: =+ROUND(BX5*0.1,2) -> 0 | BZ5: =+SUM(BX5:BY5) -> 0 | CA5: =+AD5+AI5+AN5+AS5+AX5+BC5+BH5+BM5+BR5+BW5 -> 0 | CB5: =+AE5+AJ5+AO5+AT5+AY5+BD5+BI5+BN5+BS5+BX5 -> 0 | CC5: =+AF5+AK5+AP5+AU5+AZ5+BE5+BJ5+BO5+BT5+BY5 -> 0 | CD5: =+SUM(CB5:CC5) -> 0 | CE5: =ROUND(IF($Y5<>"",$Z5,$T5)-CB5,2) -> 0 | CF5: =ROUND(IF($Y5<>"",$AA5,$U5)-CC5,2) -> 0 | CG5: GERENCIA DE TRANSPORTE PUBLICO Y CIRCULACION VIAL | CH5: Pamela Aida Flores Laqui | CI5: Gerente | CJ5: 951 902 578
A6: 5 | B6: 236 | C6: MOQUEGUA | D6: ILO | E6: ILO | F6: MO-612 | G6: EMP. PE-36 (ROTARY) - TERMINAL TERRESTRE - EMP. PE-1S D (KM 04+708) | H6: 4.708 | I6: PAVIMENTADO | J6: 880 | K6: 270 | L6: 37287 | M6: 3729 | N6: 41016 | O6: EXCLUIDO | Q6: =+$K6 -> 270 | S6: =IF(Q6+R6=0,"",Q6+R6-1) -> 269 | U6: =+ROUND(T6*0.1,2) -> 0 | V6: =+SUM(T6:U6) -> 0 | X6: =+$R6 -> 0 | Y6: =IF(W6>0,X6+W6-1,"") | AA6: =+ROUND(Z6*0.1,2) -> 0 | AB6: =+SUM(Z6:AA6) -> 0 | AD6: =MAX(0,MIN(IF($Y6<>"",$Y6,$S6),AD$1)-MAX($R6,EOMONTH(AD$1,-1)+1)+1) -> 0 | AE6: =ROUND(IF($Z6="",$T6,$Z6)*(AD6/IF($W6="",$Q6,$W6)),2) -> 0 | AF6: =+ROUND(AE6*0.1,2) -> 0 | AG6: =+SUM(AE6:AF6) -> 0 | AI6: =MAX(0,MIN(IF($Y6<>"",$Y6,$S6),AI$1)-MAX($R6,EOMONTH(AI$1,-1)+1)+1) -> 0 | AJ6: =ROUND(IF($Z6="",$T6,$Z6)*(AI6/IF($W6="",$Q6,$W6)),2) -> 0 | AK6: =+ROUND(AJ6*0.1,2) -> 0 | AL6: =+SUM(AJ6:AK6) -> 0 | AN6: =MAX(0,MIN(IF($Y6<>"",$Y6,$S6),AN$1)-MAX($R6,EOMONTH(AN$1,-1)+1)+1) -> 0 | AO6: =ROUND(IF($Z6="",$T6,$Z6)*(AN6/IF($W6="",$Q6,$W6)),2) -> 0 | AP6: =+ROUND(AO6*0.1,2) -> 0 | AQ6: =+SUM(AO6:AP6) -> 0 | AS6: =MAX(0,MIN(IF($Y6<>"",$Y6,$S6),AS$1)-MAX($R6,EOMONTH(AS$1,-1)+1)+1) -> 0 | AT6: =ROUND(IF($Z6="",$T6,$Z6)*(AS6/IF($W6="",$Q6,$W6)),2) -> 0 | AU6: =+ROUND(AT6*0.1,2) -> 0 | AV6: =+SUM(AT6:AU6) -> 0 | AX6: =MAX(0,MIN(IF($Y6<>"",$Y6,$S6),AX$1)-MAX($R6,EOMONTH(AX$1,-1)+1)+1) -> 0 | AY6: =ROUND(IF($Z6="",$T6,$Z6)*(AX6/IF($W6="",$Q6,$W6)),2) -> 0 | AZ6: =+ROUND(AY6*0.1,2) -> 0 | BA6: =+SUM(AY6:AZ6) -> 0 | BC6: =MAX(0,MIN(IF($Y6<>"",$Y6,$S6),BC$1)-MAX($R6,EOMONTH(BC$1,-1)+1)+1) -> 0 | BD6: =ROUND(IF($Z6="",$T6,$Z6)*(BC6/IF($W6="",$Q6,$W6)),2) -> 0 | BE6: =+ROUND(BD6*0.1,2) -> 0 | BF6: =+SUM(BD6:BE6) -> 0 | BH6: =MAX(0,MIN(IF($Y6<>"",$Y6,$S6),BH$1)-MAX($R6,EOMONTH(BH$1,-1)+1)+1) -> 0 | BI6: =ROUND(IF($Z6="",$T6,$Z6)*(BH6/IF($W6="",$Q6,$W6)),2) -> 0 | BJ6: =+ROUND(BI6*0.1,2) -> 0 | BK6: =+SUM(BI6:BJ6) -> 0 | BM6: =MAX(0,MIN(IF($Y6<>"",$Y6,$S6),BM$1)-MAX($R6,EOMONTH(BM$1,-1)+1)+1) -> 0 | BN6: =ROUND(IF($Z6="",$T6,$Z6)*(BM6/IF($W6="",$Q6,$W6)),2) -> 0 | BO6: =+ROUND(BN6*0.1,2) -> 0 | BP6: =+SUM(BN6:BO6) -> 0 | BR6: =MAX(0,MIN(IF($Y6<>"",$Y6,$S6),BR$1)-MAX($R6,EOMONTH(BR$1,-1)+1)+1) -> 0 | BS6: =ROUND(IF($Z6="",$T6,$Z6)*(BR6/IF($W6="",$Q6,$W6)),2) -> 0 | BT6: =+ROUND(BS6*0.1,2) -> 0 | BU6: =+SUM(BS6:BT6) -> 0 | BW6: =MAX(0,MIN(IF($Y6<>"",$Y6,$S6),BW$1)-MAX($R6,EOMONTH(BW$1,-1)+1)+1) -> 0 | BX6: =ROUND(IF($Z6="",$T6,$Z6)*(BW6/IF($W6="",$Q6,$W6)),2) -> 0 | BY6: =+ROUND(BX6*0.1,2) -> 0 | BZ6: =+SUM(BX6:BY6) -> 0 | CA6: =+AD6+AI6+AN6+AS6+AX6+BC6+BH6+BM6+BR6+BW6 -> 0 | CB6: =+AE6+AJ6+AO6+AT6+AY6+BD6+BI6+BN6+BS6+BX6 -> 0 | CC6: =+AF6+AK6+AP6+AU6+AZ6+BE6+BJ6+BO6+BT6+BY6 -> 0 | CD6: =+SUM(CB6:CC6) -> 0 | CE6: =ROUND(IF($Y6<>"",$Z6,$T6)-CB6,2) -> 0 | CF6: =ROUND(IF($Y6<>"",$AA6,$U6)-CC6,2) -> 0 | CG6: GERENCIA DE TRANSPORTE PUBLICO Y CIRCULACION VIAL | CH6: Pamela Aida Flores Laqui | CI6: Gerente | CJ6: 951 902 578
A7: 6 | B7: 49 | C7: MOQUEGUA | D7: MARISCAL NIETO | E7: CARUMAS | F7: MO-549 | G7: EMP. PE-36 B (TITIRI) - ARUNTAYA - CACHIMOCO - PASTO GRANDE WILLACOLLO - LORIPUNGO - EMP. PE-36 A (L. D. PUNO) (KM 51+600) | H7: 51.6 | I7: AFIRMADO | J7: 735 | K7: 247 | L7: 312257 | M7: 31226 | N7: 343483 | Q7: =+$K7 -> 247 | S7: =IF(Q7+R7=0,"",Q7+R7-1) -> 246 | U7: =+ROUND(T7*0.1,2) -> 0 | V7: =+SUM(T7:U7) -> 0 | X7: =+$R7 -> 0 | Y7: =IF(W7>0,X7+W7-1,"") | AA7: =+ROUND(Z7*0.1,2) -> 0 | AB7: =+SUM(Z7:AA7) -> 0 | AD7: =MAX(0,MIN(IF($Y7<>"",$Y7,$S7),AD$1)-MAX($R7,EOMONTH(AD$1,-1)+1)+1) -> 0 | AE7: =ROUND(IF($Z7="",$T7,$Z7)*(AD7/IF($W7="",$Q7,$W7)),2) -> 0 | AF7: =+ROUND(AE7*0.1,2) -> 0 | AG7: =+SUM(AE7:AF7) -> 0 | AI7: =MAX(0,MIN(IF($Y7<>"",$Y7,$S7),AI$1)-MAX($R7,EOMONTH(AI$1,-1)+1)+1) -> 0 | AJ7: =ROUND(IF($Z7="",$T7,$Z7)*(AI7/IF($W7="",$Q7,$W7)),2) -> 0 | AK7: =+ROUND(AJ7*0.1,2) -> 0 | AL7: =+SUM(AJ7:AK7) -> 0 | AN7: =MAX(0,MIN(IF($Y7<>"",$Y7,$S7),AN$1)-MAX($R7,EOMONTH(AN$1,-1)+1)+1) -> 0 | AO7: =ROUND(IF($Z7="",$T7,$Z7)*(AN7/IF($W7="",$Q7,$W7)),2) -> 0 | AP7: =+ROUND(AO7*0.1,2) -> 0 | AQ7: =+SUM(AO7:AP7) -> 0 | AS7: =MAX(0,MIN(IF($Y7<>"",$Y7,$S7),AS$1)-MAX($R7,EOMONTH(AS$1,-1)+1)+1) -> 0 | AT7: =ROUND(IF($Z7="",$T7,$Z7)*(AS7/IF($W7="",$Q7,$W7)),2) -> 0 | AU7: =+ROUND(AT7*0.1,2) -> 0 | AV7: =+SUM(AT7:AU7) -> 0 | AX7: =MAX(0,MIN(IF($Y7<>"",$Y7,$S7),AX$1)-MAX($R7,EOMONTH(AX$1,-1)+1)+1) -> 0 | AY7: =ROUND(IF($Z7="",$T7,$Z7)*(AX7/IF($W7="",$Q7,$W7)),2) -> 0 | AZ7: =+ROUND(AY7*0.1,2) -> 0 | BA7: =+SUM(AY7:AZ7) -> 0 | BC7: =MAX(0,MIN(IF($Y7<>"",$Y7,$S7),BC$1)-MAX($R7,EOMONTH(BC$1,-1)+1)+1) -> 0 | BD7: =ROUND(IF($Z7="",$T7,$Z7)*(BC7/IF($W7="",$Q7,$W7)),2) -> 0 | BE7: =+ROUND(BD7*0.1,2) -> 0 | BF7: =+SUM(BD7:BE7) -> 0 | BH7: =MAX(0,MIN(IF($Y7<>"",$Y7,$S7),BH$1)-MAX($R7,EOMONTH(BH$1,-1)+1)+1) -> 0 | BI7: =ROUND(IF($Z7="",$T7,$Z7)*(BH7/IF($W7="",$Q7,$W7)),2) -> 0 | BJ7: =+ROUND(BI7*0.1,2) -> 0 | BK7: =+SUM(BI7:BJ7) -> 0 | BM7: =MAX(0,MIN(IF($Y7<>"",$Y7,$S7),BM$1)-MAX($R7,EOMONTH(BM$1,-1)+1)+1) -> 0 | BN7: =ROUND(IF($Z7="",$T7,$Z7)*(BM7/IF($W7="",$Q7,$W7)),2) -> 0 | BO7: =+ROUND(BN7*0.1,2) -> 0 | BP7: =+SUM(BN7:BO7) -> 0 | BR7: =MAX(0,MIN(IF($Y7<>"",$Y7,$S7),BR$1)-MAX($R7,EOMONTH(BR$1,-1)+1)+1) -> 0 | BS7: =ROUND(IF($Z7="",$T7,$Z7)*(BR7/IF($W7="",$Q7,$W7)),2) -> 0 | BT7: =+ROUND(BS7*0.1,2) -> 0 | BU7: =+SUM(BS7:BT7) -> 0 | BW7: =MAX(0,MIN(IF($Y7<>"",$Y7,$S7),BW$1)-MAX($R7,EOMONTH(BW$1,-1)+1)+1) -> 0 | BX7: =ROUND(IF($Z7="",$T7,$Z7)*(BW7/IF($W7="",$Q7,$W7)),2) -> 0 | BY7: =+ROUND(BX7*0.1,2) -> 0 | BZ7: =+SUM(BX7:BY7) -> 0 | CA7: =+AD7+AI7+AN7+AS7+AX7+BC7+BH7+BM7+BR7+BW7 -> 0 | CB7: =+AE7+AJ7+AO7+AT7+AY7+BD7+BI7+BN7+BS7+BX7 -> 0 | CC7: =+AF7+AK7+AP7+AU7+AZ7+BE7+BJ7+BO7+BT7+BY7 -> 0 | CD7: =+SUM(CB7:CC7) -> 0 | CE7: =ROUND(IF($Y7<>"",$Z7,$T7)-CB7,2) -> 0 | CF7: =ROUND(IF($Y7<>"",$AA7,$U7)-CC7,2) -> 0 | CG7: IVP MARISCAL NIETO | CH7: Wilbert Alfredo Paredes Choquehuanca | CI7: Gerente | CJ7: 979 589 720
A8: 7 | B8: 49 | C8: MOQUEGUA | D8: MARISCAL NIETO | E8: SAN ANTONIO | F8: R1801290 | G8: EMP. PE-1S (CALALUNA) - SAN ANTONIO - COPOCROP - EMP. MO-603 (KM 05+485) | H8: 5.485 | I8: AFIRMADO | J8: 735 | K8: 271 | L8: 36418 | M8: 3642 | N8: 40060 | O8: OS-055-DT | P8: AVCOC EIRL | Q8: 240 | R8: 46144 | S8: =IF(Q8+R8=0,"",Q8+R8-1) -> 46383 | T8: 32251.8 | U8: =+ROUND(T8*0.1,2) -> 3225.18 | V8: =+SUM(T8:U8) -> 35476.98 | X8: =+$R8 -> 46144 | Y8: =IF(W8>0,X8+W8-1,"") | AA8: =+ROUND(Z8*0.1,2) -> 0 | AB8: =+SUM(Z8:AA8) -> 0 | AD8: =MAX(0,MIN(IF($Y8<>"",$Y8,$S8),AD$1)-MAX($R8,EOMONTH(AD$1,-1)+1)+1) -> 0 | AE8: =ROUND(IF($Z8="",$T8,$Z8)*(AD8/IF($W8="",$Q8,$W8)),2) -> 0 | AF8: =+ROUND(AE8*0.1,2) -> 0 | AG8: =+SUM(AE8:AF8) -> 0 | AI8: =MAX(0,MIN(IF($Y8<>"",$Y8,$S8),AI$1)-MAX($R8,EOMONTH(AI$1,-1)+1)+1) -> 0 | AJ8: =ROUND(IF($Z8="",$T8,$Z8)*(AI8/IF($W8="",$Q8,$W8)),2) -> 0 | AK8: =+ROUND(AJ8*0.1,2) -> 0 | AL8: =+SUM(AJ8:AK8) -> 0 | AN8: =MAX(0,MIN(IF($Y8<>"",$Y8,$S8),AN$1)-MAX($R8,EOMONTH(AN$1,-1)+1)+1) -> 30 | AO8: =ROUND(IF($Z8="",$T8,$Z8)*(AN8/IF($W8="",$Q8,$W8)),2) -> 4031.48 | AP8: =+ROUND(AO8*0.1,2) -> 403.15 | AQ8: =+SUM(AO8:AP8) -> 4434.63 | AS8: =MAX(0,MIN(IF($Y8<>"",$Y8,$S8),AS$1)-MAX($R8,EOMONTH(AS$1,-1)+1)+1) -> 30 | AT8: =ROUND(IF($Z8="",$T8,$Z8)*(AS8/IF($W8="",$Q8,$W8)),2) -> 4031.48 | AU8: =+ROUND(AT8*0.1,2) -> 403.15 | AV8: =+SUM(AT8:AU8) -> 4434.63 | AX8: =MAX(0,MIN(IF($Y8<>"",$Y8,$S8),AX$1)-MAX($R8,EOMONTH(AX$1,-1)+1)+1) -> 31 | AY8: =ROUND(IF($Z8="",$T8,$Z8)*(AX8/IF($W8="",$Q8,$W8)),2) -> 4165.86 | AZ8: =+ROUND(AY8*0.1,2) -> 416.59 | BA8: =+SUM(AY8:AZ8) -> 4582.45 | BC8: =MAX(0,MIN(IF($Y8<>"",$Y8,$S8),BC$1)-MAX($R8,EOMONTH(BC$1,-1)+1)+1) -> 31 | BD8: =ROUND(IF($Z8="",$T8,$Z8)*(BC8/IF($W8="",$Q8,$W8)),2) -> 4165.86 | BE8: =+ROUND(BD8*0.1,2) -> 416.59 | BF8: =+SUM(BD8:BE8) -> 4582.45 | BH8: =MAX(0,MIN(IF($Y8<>"",$Y8,$S8),BH$1)-MAX($R8,EOMONTH(BH$1,-1)+1)+1) -> 30 | BI8: =ROUND(IF($Z8="",$T8,$Z8)*(BH8/IF($W8="",$Q8,$W8)),2) -> 4031.48 | BJ8: =+ROUND(BI8*0.1,2) -> 403.15 | BK8: =+SUM(BI8:BJ8) -> 4434.63 | BM8: =MAX(0,MIN(IF($Y8<>"",$Y8,$S8),BM$1)-MAX($R8,EOMONTH(BM$1,-1)+1)+1) -> 31 | BN8: =ROUND(IF($Z8="",$T8,$Z8)*(BM8/IF($W8="",$Q8,$W8)),2) -> 4165.86 | BO8: =+ROUND(BN8*0.1,2) -> 416.59 | BP8: =+SUM(BN8:BO8) -> 4582.45 | BR8: =MAX(0,MIN(IF($Y8<>"",$Y8,$S8),BR$1)-MAX($R8,EOMONTH(BR$1,-1)+1)+1) -> 30 | BS8: =ROUND(IF($Z8="",$T8,$Z8)*(BR8/IF($W8="",$Q8,$W8)),2) -> 4031.48 | BT8: =+ROUND(BS8*0.1,2) -> 403.15 | BU8: =+SUM(BS8:BT8) -> 4434.63 | BW8: =MAX(0,MIN(IF($Y8<>"",$Y8,$S8),BW$1)-MAX($R8,EOMONTH(BW$1,-1)+1)+1) -> 27 | BX8: =ROUND(IF($Z8="",$T8,$Z8)*(BW8/IF($W8="",$Q8,$W8)),2) -> 3628.33 | BY8: =+ROUND(BX8*0.1,2) -> 362.83 | BZ8: =+SUM(BX8:BY8) -> 3991.16 | CA8: =+AD8+AI8+AN8+AS8+AX8+BC8+BH8+BM8+BR8+BW8 -> 240 | CB8: =+AE8+AJ8+AO8+AT8+AY8+BD8+BI8+BN8+BS8+BX8 -> 32251.83 | CC8: =+AF8+AK8+AP8+AU8+AZ8+BE8+BJ8+BO8+BT8+BY8 -> 3225.2 | CD8: =+SUM(CB8:CC8) -> 35477.03 | CE8: =ROUND(IF($Y8<>"",$Z8,$T8)-CB8,2) -> -0.03 | CF8: =ROUND(IF($Y8<>"",$AA8,$U8)-CC8,2) -> -0.02 | CG8: IVP MARISCAL NIETO | CH8: Wilbert Alfredo Paredes Choquehuanca | CI8: Gerente | CJ8: 979 589 720
A9: 8 | B9: 49 | C9: MOQUEGUA | D9: MARISCAL NIETO | E9: SAN ANTONIO | F9: R1801302 | G9: EMP. PE-1S (SAN JOSÉ) - PTE. SANTO DOMINGO - LA MERCED - SACATA - EMP. MO-606 (KM 05+100) | H9: 5.1 | I9: AFIRMADO | J9: 735 | K9: 271 | L9: 33861 | M9: 3386 | N9: 37247 | O9: OS-053-DT | P9: AVCOC EIRL | Q9: 240 | R9: 46144 | S9: =IF(Q9+R9=0,"",Q9+R9-1) -> 46383 | T9: 29988 | U9: =+ROUND(T9*0.1,2) -> 2998.8 | V9: =+SUM(T9:U9) -> 32986.8 | X9: =+$R9 -> 46144 | Y9: =IF(W9>0,X9+W9-1,"") | AA9: =+ROUND(Z9*0.1,2) -> 0 | AB9: =+SUM(Z9:AA9) -> 0 | AD9: =MAX(0,MIN(IF($Y9<>"",$Y9,$S9),AD$1)-MAX($R9,EOMONTH(AD$1,-1)+1)+1) -> 0 | AE9: =ROUND(IF($Z9="",$T9,$Z9)*(AD9/IF($W9="",$Q9,$W9)),2) -> 0 | AF9: =+ROUND(AE9*0.1,2) -> 0 | AG9: =+SUM(AE9:AF9) -> 0 | AI9: =MAX(0,MIN(IF($Y9<>"",$Y9,$S9),AI$1)-MAX($R9,EOMONTH(AI$1,-1)+1)+1) -> 0 | AJ9: =ROUND(IF($Z9="",$T9,$Z9)*(AI9/IF($W9="",$Q9,$W9)),2) -> 0 | AK9: =+ROUND(AJ9*0.1,2) -> 0 | AL9: =+SUM(AJ9:AK9) -> 0 | AN9: =MAX(0,MIN(IF($Y9<>"",$Y9,$S9),AN$1)-MAX($R9,EOMONTH(AN$1,-1)+1)+1) -> 30 | AO9: =ROUND(IF($Z9="",$T9,$Z9)*(AN9/IF($W9="",$Q9,$W9)),2) -> 3748.5 | AP9: =+ROUND(AO9*0.1,2) -> 374.85 | AQ9: =+SUM(AO9:AP9) -> 4123.35 | AS9: =MAX(0,MIN(IF($Y9<>"",$Y9,$S9),AS$1)-MAX($R9,EOMONTH(AS$1,-1)+1)+1) -> 30 | AT9: =ROUND(IF($Z9="",$T9,$Z9)*(AS9/IF($W9="",$Q9,$W9)),2) -> 3748.5 | AU9: =+ROUND(AT9*0.1,2) -> 374.85 | AV9: =+SUM(AT9:AU9) -> 4123.35 | AX9: =MAX(0,MIN(IF($Y9<>"",$Y9,$S9),AX$1)-MAX($R9,EOMONTH(AX$1,-1)+1)+1) -> 31 | AY9: =ROUND(IF($Z9="",$T9,$Z9)*(AX9/IF($W9="",$Q9,$W9)),2) -> 3873.45 | AZ9: =+ROUND(AY9*0.1,2) -> 387.35 | BA9: =+SUM(AY9:AZ9) -> 4260.8 | BC9: =MAX(0,MIN(IF($Y9<>"",$Y9,$S9),BC$1)-MAX($R9,EOMONTH(BC$1,-1)+1)+1) -> 31 | BD9: =ROUND(IF($Z9="",$T9,$Z9)*(BC9/IF($W9="",$Q9,$W9)),2) -> 3873.45 | BE9: =+ROUND(BD9*0.1,2) -> 387.35 | BF9: =+SUM(BD9:BE9) -> 4260.8 | BH9: =MAX(0,MIN(IF($Y9<>"",$Y9,$S9),BH$1)-MAX($R9,EOMONTH(BH$1,-1)+1)+1) -> 30 | BI9: =ROUND(IF($Z9="",$T9,$Z9)*(BH9/IF($W9="",$Q9,$W9)),2) -> 3748.5 | BJ9: =+ROUND(BI9*0.1,2) -> 374.85 | BK9: =+SUM(BI9:BJ9) -> 4123.35 | BM9: =MAX(0,MIN(IF($Y9<>"",$Y9,$S9),BM$1)-MAX($R9,EOMONTH(BM$1,-1)+1)+1) -> 31 | BN9: =ROUND(IF($Z9="",$T9,$Z9)*(BM9/IF($W9="",$Q9,$W9)),2) -> 3873.45 | BO9: =+ROUND(BN9*0.1,2) -> 387.35 | BP9: =+SUM(BN9:BO9) -> 4260.8 | BR9: =MAX(0,MIN(IF($Y9<>"",$Y9,$S9),BR$1)-MAX($R9,EOMONTH(BR$1,-1)+1)+1) -> 30 | BS9: =ROUND(IF($Z9="",$T9,$Z9)*(BR9/IF($W9="",$Q9,$W9)),2) -> 3748.5 | BT9: =+ROUND(BS9*0.1,2) -> 374.85 | BU9: =+SUM(BS9:BT9) -> 4123.35 | BW9: =MAX(0,MIN(IF($Y9<>"",$Y9,$S9),BW$1)-MAX($R9,EOMONTH(BW$1,-1)+1)+1) -> 27 | BX9: =ROUND(IF($Z9="",$T9,$Z9)*(BW9/IF($W9="",$Q9,$W9)),2) -> 3373.65 | BY9: =+ROUND(BX9*0.1,2) -> 337.37 | BZ9: =+SUM(BX9:BY9) -> 3711.02 | CA9: =+AD9+AI9+AN9+AS9+AX9+BC9+BH9+BM9+BR9+BW9 -> 240 | CB9: =+AE9+AJ9+AO9+AT9+AY9+BD9+BI9+BN9+BS9+BX9 -> 29988 | CC9: =+AF9+AK9+AP9+AU9+AZ9+BE9+BJ9+BO9+BT9+BY9 -> 2998.82 | CD9: =+SUM(CB9:CC9) -> 32986.82 | CE9: =ROUND(IF($Y9<>"",$Z9,$T9)-CB9,2) -> 0 | CF9: =ROUND(IF($Y9<>"",$AA9,$U9)-CC9,2) -> -0.02 | CG9: IVP MARISCAL NIETO | CH9: Wilbert Alfredo Paredes Choquehuanca | CI9: Gerente | CJ9: 979 589 720
A10: 9 | B10: 49 | C10: MOQUEGUA | D10: MARISCAL NIETO | E10: MOQUEGUA | F10: MO-598 | G10: EMP. MO-590 - EL RAYO - OCOLLITA - ESTUQUIÑA - LOS ÁNGELES - EMP. MO-579 (TOMBOLOMBO) (KM 07+000) | H10: 7 | I10: PAVIMENTADO | J10: 887.5 | K10: 248 | L10: 51357 | M10: 5136 | N10: 56493 | O10: OS-083-DT | P10: AVCOC EIRL | Q10: 180 | R10: 46205 | S10: =IF(Q10+R10=0,"",Q10+R10-1) -> 46384 | T10: 37275 | U10: =+ROUND(T10*0.1,2) -> 3727.5 | V10: =+SUM(T10:U10) -> 41002.5 | X10: =+$R10 -> 46205 | Y10: =IF(W10>0,X10+W10-1,"") | AA10: =+ROUND(Z10*0.1,2) -> 0 | AB10: =+SUM(Z10:AA10) -> 0 | AD10: =MAX(0,MIN(IF($Y10<>"",$Y10,$S10),AD$1)-MAX($R10,EOMONTH(AD$1,-1)+1)+1) -> 0 | AE10: =ROUND(IF($Z10="",$T10,$Z10)*(AD10/IF($W10="",$Q10,$W10)),2) -> 0 | AF10: =+ROUND(AE10*0.1,2) -> 0 | AG10: =+SUM(AE10:AF10) -> 0 | AI10: =MAX(0,MIN(IF($Y10<>"",$Y10,$S10),AI$1)-MAX($R10,EOMONTH(AI$1,-1)+1)+1) -> 0 | AJ10: =ROUND(IF($Z10="",$T10,$Z10)*(AI10/IF($W10="",$Q10,$W10)),2) -> 0 | AK10: =+ROUND(AJ10*0.1,2) -> 0 | AL10: =+SUM(AJ10:AK10) -> 0 | AN10: =MAX(0,MIN(IF($Y10<>"",$Y10,$S10),AN$1)-MAX($R10,EOMONTH(AN$1,-1)+1)+1) -> 0 | AO10: =ROUND(IF($Z10="",$T10,$Z10)*(AN10/IF($W10="",$Q10,$W10)),2) -> 0 | AP10: =+ROUND(AO10*0.1,2) -> 0 | AQ10: =+SUM(AO10:AP10) -> 0 | AS10: =MAX(0,MIN(IF($Y10<>"",$Y10,$S10),AS$1)-MAX($R10,EOMONTH(AS$1,-1)+1)+1) -> 0 | AT10: =ROUND(IF($Z10="",$T10,$Z10)*(AS10/IF($W10="",$Q10,$W10)),2) -> 0 | AU10: =+ROUND(AT10*0.1,2) -> 0 | AV10: =+SUM(AT10:AU10) -> 0 | AX10: =MAX(0,MIN(IF($Y10<>"",$Y10,$S10),AX$1)-MAX($R10,EOMONTH(AX$1,-1)+1)+1) -> 30 | AY10: =ROUND(IF($Z10="",$T10,$Z10)*(AX10/IF($W10="",$Q10,$W10)),2) -> 6212.5 | AZ10: =+ROUND(AY10*0.1,2) -> 621.25 | BA10: =+SUM(AY10:AZ10) -> 6833.75 | BC10: =MAX(0,MIN(IF($Y10<>"",$Y10,$S10),BC$1)-MAX($R10,EOMONTH(BC$1,-1)+1)+1) -> 31 | BD10: =ROUND(IF($Z10="",$T10,$Z10)*(BC10/IF($W10="",$Q10,$W10)),2) -> 6419.58 | BE10: =+ROUND(BD10*0.1,2) -> 641.96 | BF10: =+SUM(BD10:BE10) -> 7061.54 | BH10: =MAX(0,MIN(IF($Y10<>"",$Y10,$S10),BH$1)-MAX($R10,EOMONTH(BH$1,-1)+1)+1) -> 30 | BI10: =ROUND(IF($Z10="",$T10,$Z10)*(BH10/IF($W10="",$Q10,$W10)),2) -> 6212.5 | BJ10: =+ROUND(BI10*0.1,2) -> 621.25 | BK10: =+SUM(BI10:BJ10) -> 6833.75 | BM10: =MAX(0,MIN(IF($Y10<>"",$Y10,$S10),BM$1)-MAX($R10,EOMONTH(BM$1,-1)+1)+1) -> 31 | BN10: =ROUND(IF($Z10="",$T10,$Z10)*(BM10/IF($W10="",$Q10,$W10)),2) -> 6419.58 | BO10: =+ROUND(BN10*0.1,2) -> 641.96 | BP10: =+SUM(BN10:BO10) -> 7061.54 | BR10: =MAX(0,MIN(IF($Y10<>"",$Y10,$S10),BR$1)-MAX($R10,EOMONTH(BR$1,-1)+1)+1) -> 30 | BS10: =ROUND(IF($Z10="",$T10,$Z10)*(BR10/IF($W10="",$Q10,$W10)),2) -> 6212.5 | BT10: =+ROUND(BS10*0.1,2) -> 621.25 | BU10: =+SUM(BS10:BT10) -> 6833.75 | BW10: =MAX(0,MIN(IF($Y10<>"",$Y10,$S10),BW$1)-MAX($R10,EOMONTH(BW$1,-1)+1)+1) -> 28 | BX10: =ROUND(IF($Z10="",$T10,$Z10)*(BW10/IF($W10="",$Q10,$W10)),2) -> 5798.33 | BY10: =+ROUND(BX10*0.1,2) -> 579.83 | BZ10: =+SUM(BX10:BY10) -> 6378.16 | CA10: =+AD10+AI10+AN10+AS10+AX10+BC10+BH10+BM10+BR10+BW10 -> 180 | CB10: =+AE10+AJ10+AO10+AT10+AY10+BD10+BI10+BN10+BS10+BX10 -> 37274.99 | CC10: =+AF10+AK10+AP10+AU10+AZ10+BE10+BJ10+BO10+BT10+BY10 -> 3727.5 | CD10: =+SUM(CB10:CC10) -> 41002.49 | CE10: =ROUND(IF($Y10<>"",$Z10,$T10)-CB10,2) -> 0.01 | CF10: =ROUND(IF($Y10<>"",$AA10,$U10)-CC10,2) -> 0 | CG10: IVP MARISCAL NIETO | CH10: Wilbert Alfredo Paredes Choquehuanca | CI10: Gerente | CJ10: 979 589 720
A11: 10 | B11: 49 | C11: MOQUEGUA | D11: MARISCAL NIETO | E11: TORATA | F11: MO-583 | G11: EMP. PE-36 A - IE TORATA ALTA - TORATA ALTA (KM 03+524) | H11: 3.524 | I11: PAVIMENTADO | J11: 887.5 | K11: 270 | L11: 28148 | M11: 2815 | N11: 30963 | O11: OS-054-DT | P11: AVCOC EIRL | Q11: 240 | R11: 46144 | S11: =IF(Q11+R11=0,"",Q11+R11-1) -> 46383 | T11: 25020.4 | U11: =+ROUND(T11*0.1,2) -> 2502.04 | V11: =+SUM(T11:U11) -> 27522.44 | X11: =+$R11 -> 46144 | Y11: =IF(W11>0,X11+W11-1,"") | AA11: =+ROUND(Z11*0.1,2) -> 0 | AB11: =+SUM(Z11:AA11) -> 0 | AD11: =MAX(0,MIN(IF($Y11<>"",$Y11,$S11),AD$1)-MAX($R11,EOMONTH(AD$1,-1)+1)+1) -> 0 | AE11: =ROUND(IF($Z11="",$T11,$Z11)*(AD11/IF($W11="",$Q11,$W11)),2) -> 0 | AF11: =+ROUND(AE11*0.1,2) -> 0 | AG11: =+SUM(AE11:AF11) -> 0 | AI11: =MAX(0,MIN(IF($Y11<>"",$Y11,$S11),AI$1)-MAX($R11,EOMONTH(AI$1,-1)+1)+1) -> 0 | AJ11: =ROUND(IF($Z11="",$T11,$Z11)*(AI11/IF($W11="",$Q11,$W11)),2) -> 0 | AK11: =+ROUND(AJ11*0.1,2) -> 0 | AL11: =+SUM(AJ11:AK11) -> 0 | AN11: =MAX(0,MIN(IF($Y11<>"",$Y11,$S11),AN$1)-MAX($R11,EOMONTH(AN$1,-1)+1)+1) -> 30 | AO11: 2223.55 | AP11: =+ROUND(AO11*0.1,2) -> 222.36 | AQ11: =+SUM(AO11:AP11) -> 2445.91 | AS11: =MAX(0,MIN(IF($Y11<>"",$Y11,$S11),AS$1)-MAX($R11,EOMONTH(AS$1,-1)+1)+1) -> 30 | AT11: 2728.27 | AU11: =+ROUND(AT11*0.1,2) -> 272.83 | AV11: =+SUM(AT11:AU11) -> 3001.1 | AX11: =MAX(0,MIN(IF($Y11<>"",$Y11,$S11),AX$1)-MAX($R11,EOMONTH(AX$1,-1)+1)+1) -> 31 | AY11: =ROUND(IF($Z11="",$T11,$Z11)*(AX11/IF($W11="",$Q11,$W11)),2) -> 3231.8 | AZ11: =+ROUND(AY11*0.1,2) -> 323.18 | BA11: =+SUM(AY11:AZ11) -> 3554.98 | BC11: =MAX(0,MIN(IF($Y11<>"",$Y11,$S11),BC$1)-MAX($R11,EOMONTH(BC$1,-1)+1)+1) -> 31 | BD11: =ROUND(IF($Z11="",$T11,$Z11)*(BC11/IF($W11="",$Q11,$W11)),2) -> 3231.8 | BE11: =+ROUND(BD11*0.1,2) -> 323.18 | BF11: =+SUM(BD11:BE11) -> 3554.98 | BH11: =MAX(0,MIN(IF($Y11<>"",$Y11,$S11),BH$1)-MAX($R11,EOMONTH(BH$1,-1)+1)+1) -> 30 | BI11: =ROUND(IF($Z11="",$T11,$Z11)*(BH11/IF($W11="",$Q11,$W11)),2) -> 3127.55 | BJ11: =+ROUND(BI11*0.1,2) -> 312.76 | BK11: =+SUM(BI11:BJ11) -> 3440.31 | BM11: =MAX(0,MIN(IF($Y11<>"",$Y11,$S11),BM$1)-MAX($R11,EOMONTH(BM$1,-1)+1)+1) -> 31 | BN11: =ROUND(IF($Z11="",$T11,$Z11)*(BM11/IF($W11="",$Q11,$W11)),2) -> 3231.8 | BO11: =+ROUND(BN11*0.1,2) -> 323.18 | BP11: =+SUM(BN11:BO11) -> 3554.98 | BR11: =MAX(0,MIN(IF($Y11<>"",$Y11,$S11),BR$1)-MAX($R11,EOMONTH(BR$1,-1)+1)+1) -> 30 | BS11: =ROUND(IF($Z11="",$T11,$Z11)*(BR11/IF($W11="",$Q11,$W11)),2) -> 3127.55 | BT11: =+ROUND(BS11*0.1,2) -> 312.76 | BU11: =+SUM(BS11:BT11) -> 3440.31 | BW11: =MAX(0,MIN(IF($Y11<>"",$Y11,$S11),BW$1)-MAX($R11,EOMONTH(BW$1,-1)+1)+1) -> 27 | BX11: =ROUND(IF($Z11="",$T11,$Z11)*(BW11/IF($W11="",$Q11,$W11)),2) -> 2814.8 | BY11: =+ROUND(BX11*0.1,2) -> 281.48 | BZ11: =+SUM(BX11:BY11) -> 3096.28 | CA11: =+AD11+AI11+AN11+AS11+AX11+BC11+BH11+BM11+BR11+BW11 -> 240 | CB11: =+AE11+AJ11+AO11+AT11+AY11+BD11+BI11+BN11+BS11+BX11 -> 23717.12 | CC11: =+AF11+AK11+AP11+AU11+AZ11+BE11+BJ11+BO11+BT11+BY11 -> 2371.73 | CD11: =+SUM(CB11:CC11) -> 26088.85 | CE11: =ROUND(IF($Y11<>"",$Z11,$T11)-CB11,2) -> 1303.28 | CF11: =ROUND(IF($Y11<>"",$AA11,$U11)-CC11,2) -> 130.31 | CG11: IVP MARISCAL NIETO | CH11: Wilbert Alfredo Paredes Choquehuanca | CI11: Gerente | CJ11: 979 589 720
A12: 11 | B12: 48 | C12: MOQUEGUA | D12: GENERAL SANCHEZ CERRO | E12: OMATE | F12: MO-521 | G12: OMATE(KM 01+525) - CHICHILIN ALTO - CHALLAHUAYO - CARABAYA - COHUACHO (KM 14+931) | H12: 13.406 | I12: AFIRMADO | J12: 735 | K12: 240 | L12: 78827 | M12: 7882 | N12: 86709 | O12: C_391-2026 | P12: CONSORCIO VIAL OMATE | Q12: =+$K12 -> 240 | R12: 46190 | S12: =IF(Q12+R12=0,"",Q12+R12-1) -> 46429 | T12: 74872.83 | U12: =+ROUND(T12*0.1,2) -> 7487.28 | V12: =+SUM(T12:U12) -> 82360.11 | W12: 198 | X12: =+$R12 -> 46190 | Y12: =IF(W12>0,X12+W12-1,"") -> 46387 | Z12: 61770.06 | AA12: =+ROUND(Z12*0.1,2) -> 6177.01 | AB12: =+SUM(Z12:AA12) -> 67947.07 | AD12: =MAX(0,MIN(IF($Y12<>"",$Y12,$S12),AD$1)-MAX($R12,EOMONTH(AD$1,-1)+1)+1) -> 0 | AE12: =ROUND(IF($Z12="",$T12,$Z12)*(AD12/IF($W12="",$Q12,$W12)),2) -> 0 | AF12: =+ROUND(AE12*0.1,2) -> 0 | AG12: =+SUM(AE12:AF12) -> 0 | AI12: =MAX(0,MIN(IF($Y12<>"",$Y12,$S12),AI$1)-MAX($R12,EOMONTH(AI$1,-1)+1)+1) -> 0 | AJ12: =ROUND(IF($Z12="",$T12,$Z12)*(AI12/IF($W12="",$Q12,$W12)),2) -> 0 | AK12: =+ROUND(AJ12*0.1,2) -> 0 | AL12: =+SUM(AJ12:AK12) -> 0 | AN12: =MAX(0,MIN(IF($Y12<>"",$Y12,$S12),AN$1)-MAX($R12,EOMONTH(AN$1,-1)+1)+1) -> 0 | AO12: =ROUND(IF($Z12="",$T12,$Z12)*(AN12/IF($W12="",$Q12,$W12)),2) -> 0 | AP12: =+ROUND(AO12*0.1,2) -> 0 | AQ12: =+SUM(AO12:AP12) -> 0 | AS12: =MAX(0,MIN(IF($Y12<>"",$Y12,$S12),AS$1)-MAX($R12,EOMONTH(AS$1,-1)+1)+1) -> 14 | AT12: =ROUND(IF($Z12="",$T12,$Z12)*(AS12/IF($W12="",$Q12,$W12)),2) -> 4367.58 | AU12: =+ROUND(AT12*0.1,2) -> 436.76 | AV12: =+SUM(AT12:AU12) -> 4804.34 | AX12: =MAX(0,MIN(IF($Y12<>"",$Y12,$S12),AX$1)-MAX($R12,EOMONTH(AX$1,-1)+1)+1) -> 31 | AY12: =ROUND(IF($Z12="",$T12,$Z12)*(AX12/IF($W12="",$Q12,$W12)),2) -> 9671.07 | AZ12: =+ROUND(AY12*0.1,2) -> 967.11 | BA12: =+SUM(AY12:AZ12) -> 10638.18 | BC12: =MAX(0,MIN(IF($Y12<>"",$Y12,$S12),BC$1)-MAX($R12,EOMONTH(BC$1,-1)+1)+1) -> 31 | BD12: =ROUND(IF($Z12="",$T12,$Z12)*(BC12/IF($W12="",$Q12,$W12)),2) -> 9671.07 | BE12: =+ROUND(BD12*0.1,2) -> 967.11 | BF12: =+SUM(BD12:BE12) -> 10638.18 | BH12: =MAX(0,MIN(IF($Y12<>"",$Y12,$S12),BH$1)-MAX($R12,EOMONTH(BH$1,-1)+1)+1) -> 30 | BI12: =ROUND(IF($Z12="",$T12,$Z12)*(BH12/IF($W12="",$Q12,$W12)),2) -> 9359.1 | BJ12: =+ROUND(BI12*0.1,2) -> 935.91 | BK12: =+SUM(BI12:BJ12) -> 10295.01 | BM12: =MAX(0,MIN(IF($Y12<>"",$Y12,$S12),BM$1)-MAX($R12,EOMONTH(BM$1,-1)+1)+1) -> 31 | BN12: =ROUND(IF($Z12="",$T12,$Z12)*(BM12/IF($W12="",$Q12,$W12)),2) -> 9671.07 | BO12: =+ROUND(BN12*0.1,2) -> 967.11 | BP12: =+SUM(BN12:BO12) -> 10638.18 | BR12: =MAX(0,MIN(IF($Y12<>"",$Y12,$S12),BR$1)-MAX($R12,EOMONTH(BR$1,-1)+1)+1) -> 30 | BS12: =ROUND(IF($Z12="",$T12,$Z12)*(BR12/IF($W12="",$Q12,$W12)),2) -> 9359.1 | BT12: =+ROUND(BS12*0.1,2) -> 935.91 | BU12: =+SUM(BS12:BT12) -> 10295.01 | BW12: =MAX(0,MIN(IF($Y12<>"",$Y12,$S12),BW$1)-MAX($R12,EOMONTH(BW$1,-1)+1)+1) -> 31 | BX12: =ROUND(IF($Z12="",$T12,$Z12)*(BW12/IF($W12="",$Q12,$W12)),2) -> 9671.07 | BY12: =+ROUND(BX12*0.1,2) -> 967.11 | BZ12: =+SUM(BX12:BY12) -> 10638.18 | CA12: =+AD12+AI12+AN12+AS12+AX12+BC12+BH12+BM12+BR12+BW12 -> 198 | CB12: =+AE12+AJ12+AO12+AT12+AY12+BD12+BI12+BN12+BS12+BX12 -> 61770.06 | CC12: =+AF12+AK12+AP12+AU12+AZ12+BE12+BJ12+BO12+BT12+BY12 -> 6177.02 | CD12: =+SUM(CB12:CC12) -> 67947.08 | CE12: =ROUND(IF($Y12<>"",$Z12,$T12)-CB12,2) -> 0 | CF12: =ROUND(IF($Y12<>"",$AA12,$U12)-CC12,2) -> -0.01 | CG12: IVP GENERAL SANCHEZ CERRO | CH12: Miler Barrientos Ramos | CI12: Gerente | CJ12: 959 090 019 | CK12: Miler Barrientos Ramos | CL12: Memorando N° 0195-2026/MPGSC/GM/AFPT | CM12: 46112 | CN12: 959 090 019
A13: 12 | B13: 48 | C13: MOQUEGUA | D13: GENERAL SANCHEZ CERRO | E13: OMATE | F13: MO-524 | G13: PUENTE OMATE (KM 1+041) - ANEXO LAJE (KM 1+587), LAJE ( KM 1+952) - CAPILLA VIRGEN COPACABANA (2+386), ANEXO SABAYA ( KM 02+ 534) - SAN MIGUEL (3+476), SAN FRANCISCO (KM 5+689) - I.E. N°43057 - URINAY (7+336) | H13: 13.406 | I13: AFIRMADO | J13: 735 | K13: 261 | L13: 29402 | M13: 2940 | N13: 32342 | O13: OS-519 | P13: ASOCIACIÓN DE MANTENIMIENTO DE VÍAS VECINALES RURALES Y URBANOS SAN BERNARDO | Q13: =+$K13 -> 261 | R13: 46104 | S13: =IF(Q13+R13=0,"",Q13+R13-1) -> 46364 | T13: 28250 | U13: =+ROUND(T13*0.1,2) -> 2825 | V13: =+SUM(T13:U13) -> 31075 | X13: =+$R13 -> 46104 | Y13: =IF(W13>0,X13+W13-1,"") | AA13: =+ROUND(Z13*0.1,2) -> 0 | AB13: =+SUM(Z13:AA13) -> 0 | AD13: =MAX(0,MIN(IF($Y13<>"",$Y13,$S13),AD$1)-MAX($R13,EOMONTH(AD$1,-1)+1)+1) -> 9 | AE13: =ROUND(IF($Z13="",$T13,$Z13)*(AD13/IF($W13="",$Q13,$W13)),2) -> 974.14 | AF13: =+ROUND(AE13*0.1,2) -> 97.41 | AG13: =+SUM(AE13:AF13) -> 1071.55 | AI13: =MAX(0,MIN(IF($Y13<>"",$Y13,$S13),AI$1)-MAX($R13,EOMONTH(AI$1,-1)+1)+1) -> 30 | AJ13: =ROUND(IF($Z13="",$T13,$Z13)*(AI13/IF($W13="",$Q13,$W13)),2) -> 3247.13 | AK13: =+ROUND(AJ13*0.1,2) -> 324.71 | AL13: =+SUM(AJ13:AK13) -> 3571.84 | AN13: =MAX(0,MIN(IF($Y13<>"",$Y13,$S13),AN$1)-MAX($R13,EOMONTH(AN$1,-1)+1)+1) -> 31 | AO13: =ROUND(IF($Z13="",$T13,$Z13)*(AN13/IF($W13="",$Q13,$W13)),2) -> 3355.36 | AP13: =+ROUND(AO13*0.1,2) -> 335.54 | AQ13: =+SUM(AO13:AP13) -> 3690.9 | AS13: =MAX(0,MIN(IF($Y13<>"",$Y13,$S13),AS$1)-MAX($R13,EOMONTH(AS$1,-1)+1)+1) -> 30 | AT13: =ROUND(IF($Z13="",$T13,$Z13)*(AS13/IF($W13="",$Q13,$W13)),2) -> 3247.13 | AU13: =+ROUND(AT13*0.1,2) -> 324.71 | AV13: =+SUM(AT13:AU13) -> 3571.84 | AX13: =MAX(0,MIN(IF($Y13<>"",$Y13,$S13),AX$1)-MAX($R13,EOMONTH(AX$1,-1)+1)+1) -> 31 | AY13: =ROUND(IF($Z13="",$T13,$Z13)*(AX13/IF($W13="",$Q13,$W13)),2) -> 3355.36 | AZ13: =+ROUND(AY13*0.1,2) -> 335.54 | BA13: =+SUM(AY13:AZ13) -> 3690.9 | BC13: =MAX(0,MIN(IF($Y13<>"",$Y13,$S13),BC$1)-MAX($R13,EOMONTH(BC$1,-1)+1)+1) -> 31 | BD13: =ROUND(IF($Z13="",$T13,$Z13)*(BC13/IF($W13="",$Q13,$W13)),2) -> 3355.36 | BE13: =+ROUND(BD13*0.1,2) -> 335.54 | BF13: =+SUM(BD13:BE13) -> 3690.9 | BH13: =MAX(0,MIN(IF($Y13<>"",$Y13,$S13),BH$1)-MAX($R13,EOMONTH(BH$1,-1)+1)+1) -> 30 | BI13: =ROUND(IF($Z13="",$T13,$Z13)*(BH13/IF($W13="",$Q13,$W13)),2) -> 3247.13 | BJ13: =+ROUND(BI13*0.1,2) -> 324.71 | BK13: =+SUM(BI13:BJ13) -> 3571.84 | BM13: =MAX(0,MIN(IF($Y13<>"",$Y13,$S13),BM$1)-MAX($R13,EOMONTH(BM$1,-1)+1)+1) -> 31 | BN13: =ROUND(IF($Z13="",$T13,$Z13)*(BM13/IF($W13="",$Q13,$W13)),2) -> 3355.36 | BO13: =+ROUND(BN13*0.1,2) -> 335.54 | BP13: =+SUM(BN13:BO13) -> 3690.9 | BR13: =MAX(0,MIN(IF($Y13<>"",$Y13,$S13),BR$1)-MAX($R13,EOMONTH(BR$1,-1)+1)+1) -> 30 | BS13: =ROUND(IF($Z13="",$T13,$Z13)*(BR13/IF($W13="",$Q13,$W13)),2) -> 3247.13 | BT13: =+ROUND(BS13*0.1,2) -> 324.71 | BU13: =+SUM(BS13:BT13) -> 3571.84 | BW13: =MAX(0,MIN(IF($Y13<>"",$Y13,$S13),BW$1)-MAX($R13,EOMONTH(BW$1,-1)+1)+1) -> 8 | BX13: =ROUND(IF($Z13="",$T13,$Z13)*(BW13/IF($W13="",$Q13,$W13)),2) -> 865.9 | BY13: =+ROUND(BX13*0.1,2) -> 86.59 | BZ13: =+SUM(BX13:BY13) -> 952.49 | CA13: =+AD13+AI13+AN13+AS13+AX13+BC13+BH13+BM13+BR13+BW13 -> 261 | CB13: =+AE13+AJ13+AO13+AT13+AY13+BD13+BI13+BN13+BS13+BX13 -> 28250 | CC13: =+AF13+AK13+AP13+AU13+AZ13+BE13+BJ13+BO13+BT13+BY13 -> 2825 | CD13: =+SUM(CB13:CC13) -> 31075 | CE13: =ROUND(IF($Y13<>"",$Z13,$T13)-CB13,2) -> 0 | CF13: =ROUND(IF($Y13<>"",$AA13,$U13)-CC13,2) -> 0 | CG13: IVP GENERAL SANCHEZ CERRO | CH13: Miler Barrientos Ramos | CI13: Gerente | CJ13: 959 090 019 | CK13: Miler Barrientos Ramos | CL13: Memorando N° 0195-2026/MPGSC/GM/AFPT | CM13: 46112 | CN13: 959 090 019
A14: 13 | B14: 48 | C14: MOQUEGUA | D14: GENERAL SANCHEZ CERRO | E14: OMATE | F14: R180221 | G14: EMP. MO-522 - ACHICARI - HUASALON - QUINISTACAS - EMP. MO-521 (CHALLAHUAYO) | H14: 4.078 | I14: AFIRMADO | J14: 735 | K14: 261 | L14: 26077 | M14: 2608 | N14: 28685 | O14: OS-180 | P14: ASOCIACIÓN CIVIL SAGRADO CORAZÓN DE JESÚS-OMATE - ASSACOJE | Q14: =+$K14 -> 261 | R14: 46105 | S14: =IF(Q14+R14=0,"",Q14+R14-1) -> 46365 | T14: 25000 | U14: =+ROUND(T14*0.1,2) -> 2500 | V14: =+SUM(T14:U14) -> 27500 | X14: =+$R14 -> 46105 | Y14: =IF(W14>0,X14+W14-1,"") | AA14: =+ROUND(Z14*0.1,2) -> 0 | AB14: =+SUM(Z14:AA14) -> 0 | AD14: =MAX(0,MIN(IF($Y14<>"",$Y14,$S14),AD$1)-MAX($R14,EOMONTH(AD$1,-1)+1)+1) -> 8 | AE14: =ROUND(IF($Z14="",$T14,$Z14)*(AD14/IF($W14="",$Q14,$W14)),2) -> 766.28 | AF14: =+ROUND(AE14*0.1,2) -> 76.63 | AG14: =+SUM(AE14:AF14) -> 842.91 | AI14: =MAX(0,MIN(IF($Y14<>"",$Y14,$S14),AI$1)-MAX($R14,EOMONTH(AI$1,-1)+1)+1) -> 30 | AJ14: =ROUND(IF($Z14="",$T14,$Z14)*(AI14/IF($W14="",$Q14,$W14)),2) -> 2873.56 | AK14: =+ROUND(AJ14*0.1,2) -> 287.36 | AL14: =+SUM(AJ14:AK14) -> 3160.92 | AN14: =MAX(0,MIN(IF($Y14<>"",$Y14,$S14),AN$1)-MAX($R14,EOMONTH(AN$1,-1)+1)+1) -> 31 | AO14: =ROUND(IF($Z14="",$T14,$Z14)*(AN14/IF($W14="",$Q14,$W14)),2) -> 2969.35 | AP14: =+ROUND(AO14*0.1,2) -> 296.94 | AQ14: =+SUM(AO14:AP14) -> 3266.29 | AS14: =MAX(0,MIN(IF($Y14<>"",$Y14,$S14),AS$1)-MAX($R14,EOMONTH(AS$1,-1)+1)+1) -> 30 | AT14: =ROUND(IF($Z14="",$T14,$Z14)*(AS14/IF($W14="",$Q14,$W14)),2) -> 2873.56 | AU14: =+ROUND(AT14*0.1,2) -> 287.36 | AV14: =+SUM(AT14:AU14) -> 3160.92 | AX14: =MAX(0,MIN(IF($Y14<>"",$Y14,$S14),AX$1)-MAX($R14,EOMONTH(AX$1,-1)+1)+1) -> 31 | AY14: =ROUND(IF($Z14="",$T14,$Z14)*(AX14/IF($W14="",$Q14,$W14)),2) -> 2969.35 | AZ14: =+ROUND(AY14*0.1,2) -> 296.94 | BA14: =+SUM(AY14:AZ14) -> 3266.29 | BC14: =MAX(0,MIN(IF($Y14<>"",$Y14,$S14),BC$1)-MAX($R14,EOMONTH(BC$1,-1)+1)+1) -> 31 | BD14: =ROUND(IF($Z14="",$T14,$Z14)*(BC14/IF($W14="",$Q14,$W14)),2) -> 2969.35 | BE14: =+ROUND(BD14*0.1,2) -> 296.94 | BF14: =+SUM(BD14:BE14) -> 3266.29 | BH14: =MAX(0,MIN(IF($Y14<>"",$Y14,$S14),BH$1)-MAX($R14,EOMONTH(BH$1,-1)+1)+1) -> 30 | BI14: =ROUND(IF($Z14="",$T14,$Z14)*(BH14/IF($W14="",$Q14,$W14)),2) -> 2873.56 | BJ14: =+ROUND(BI14*0.1,2) -> 287.36 | BK14: =+SUM(BI14:BJ14) -> 3160.92 | BM14: =MAX(0,MIN(IF($Y14<>"",$Y14,$S14),BM$1)-MAX($R14,EOMONTH(BM$1,-1)+1)+1) -> 31 | BN14: =ROUND(IF($Z14="",$T14,$Z14)*(BM14/IF($W14="",$Q14,$W14)),2) -> 2969.35 | BO14: =+ROUND(BN14*0.1,2) -> 296.94 | BP14: =+SUM(BN14:BO14) -> 3266.29 | BR14: =MAX(0,MIN(IF($Y14<>"",$Y14,$S14),BR$1)-MAX($R14,EOMONTH(BR$1,-1)+1)+1) -> 30 | BS14: =ROUND(IF($Z14="",$T14,$Z14)*(BR14/IF($W14="",$Q14,$W14)),2) -> 2873.56 | BT14: =+ROUND(BS14*0.1,2) -> 287.36 | BU14: =+SUM(BS14:BT14) -> 3160.92 | BW14: =MAX(0,MIN(IF($Y14<>"",$Y14,$S14),BW$1)-MAX($R14,EOMONTH(BW$1,-1)+1)+1) -> 9 | BX14: =ROUND(IF($Z14="",$T14,$Z14)*(BW14/IF($W14="",$Q14,$W14)),2) -> 862.07 | BY14: =+ROUND(BX14*0.1,2) -> 86.21 | BZ14: =+SUM(BX14:BY14) -> 948.28 | CA14: =+AD14+AI14+AN14+AS14+AX14+BC14+BH14+BM14+BR14+BW14 -> 261 | CB14: =+AE14+AJ14+AO14+AT14+AY14+BD14+BI14+BN14+BS14+BX14 -> 24999.99 | CC14: =+AF14+AK14+AP14+AU14+AZ14+BE14+BJ14+BO14+BT14+BY14 -> 2500.04 | CD14: =+SUM(CB14:CC14) -> 27500.03 | CE14: =ROUND(IF($Y14<>"",$Z14,$T14)-CB14,2) -> 0.01 | CF14: =ROUND(IF($Y14<>"",$AA14,$U14)-CC14,2) -> -0.04 | CG14: IVP GENERAL SANCHEZ CERRO | CH14: Miler Barrientos Ramos | CI14: Gerente | CJ14: 959 090 019 | CK14: Miler Barrientos Ramos | CL14: Memorando N° 0195-2026/MPGSC/GM/AFPT | CM14: 46112 | CN14: 959 090 019
A15: 14 | B15: 48 | C15: MOQUEGUA | D15: GENERAL SANCHEZ CERRO | E15: PUQUINA | F15: MO-511 | G15: PUQUINA (KM 01+245) - POCOHUAYO (KM 7+151), POCOHUAYO (KM 07+438) - TILIA - EMP. MO-512 (KM 10+748) | H15: 9.216 | I15: AFIRMADO | J15: 735 | K15: 240 | L15: 54190 | M15: 5419 | N15: 59609 | O15: C_389-2026 | P15: CONSORCIO VIAL OMATE | Q15: =+$K15 -> 240 | R15: 46190 | S15: =IF(Q15+R15=0,"",Q15+R15-1) -> 46429 | T15: 51442.5 | U15: =+ROUND(T15*0.1,2) -> 5144.25 | V15: =+SUM(T15:U15) -> 56586.75 | W15: 198 | X15: =+$R15 -> 46190 | Y15: =IF(W15>0,X15+W15-1,"") -> 46387 | Z15: 42440.07 | AA15: =+ROUND(Z15*0.1,2) -> 4244.01 | AB15: =+SUM(Z15:AA15) -> 46684.08 | AD15: =MAX(0,MIN(IF($Y15<>"",$Y15,$S15),AD$1)-MAX($R15,EOMONTH(AD$1,-1)+1)+1) -> 0 | AE15: =ROUND(IF($Z15="",$T15,$Z15)*(AD15/IF($W15="",$Q15,$W15)),2) -> 0 | AF15: =+ROUND(AE15*0.1,2) -> 0 | AG15: =+SUM(AE15:AF15) -> 0 | AI15: =MAX(0,MIN(IF($Y15<>"",$Y15,$S15),AI$1)-MAX($R15,EOMONTH(AI$1,-1)+1)+1) -> 0 | AJ15: =ROUND(IF($Z15="",$T15,$Z15)*(AI15/IF($W15="",$Q15,$W15)),2) -> 0 | AK15: =+ROUND(AJ15*0.1,2) -> 0 | AL15: =+SUM(AJ15:AK15) -> 0 | AN15: =MAX(0,MIN(IF($Y15<>"",$Y15,$S15),AN$1)-MAX($R15,EOMONTH(AN$1,-1)+1)+1) -> 0 | AO15: =ROUND(IF($Z15="",$T15,$Z15)*(AN15/IF($W15="",$Q15,$W15)),2) -> 0 | AP15: =+ROUND(AO15*0.1,2) -> 0 | AQ15: =+SUM(AO15:AP15) -> 0 | AS15: =MAX(0,MIN(IF($Y15<>"",$Y15,$S15),AS$1)-MAX($R15,EOMONTH(AS$1,-1)+1)+1) -> 14 | AT15: =ROUND(IF($Z15="",$T15,$Z15)*(AS15/IF($W15="",$Q15,$W15)),2) -> 3000.81 | AU15: =+ROUND(AT15*0.1,2) -> 300.08 | AV15: =+SUM(AT15:AU15) -> 3300.89 | AX15: =MAX(0,MIN(IF($Y15<>"",$Y15,$S15),AX$1)-MAX($R15,EOMONTH(AX$1,-1)+1)+1) -> 31 | AY15: =ROUND(IF($Z15="",$T15,$Z15)*(AX15/IF($W15="",$Q15,$W15)),2) -> 6644.66 | AZ15: =+ROUND(AY15*0.1,2) -> 664.47 | BA15: =+SUM(AY15:AZ15) -> 7309.13 | BC15: =MAX(0,MIN(IF($Y15<>"",$Y15,$S15),BC$1)-MAX($R15,EOMONTH(BC$1,-1)+1)+1) -> 31 | BD15: =ROUND(IF($Z15="",$T15,$Z15)*(BC15/IF($W15="",$Q15,$W15)),2) -> 6644.66 | BE15: =+ROUND(BD15*0.1,2) -> 664.47 | BF15: =+SUM(BD15:BE15) -> 7309.13 | BH15: =MAX(0,MIN(IF($Y15<>"",$Y15,$S15),BH$1)-MAX($R15,EOMONTH(BH$1,-1)+1)+1) -> 30 | BI15: =ROUND(IF($Z15="",$T15,$Z15)*(BH15/IF($W15="",$Q15,$W15)),2) -> 6430.31 | BJ15: =+ROUND(BI15*0.1,2) -> 643.03 | BK15: =+SUM(BI15:BJ15) -> 7073.34 | BM15: =MAX(0,MIN(IF($Y15<>"",$Y15,$S15),BM$1)-MAX($R15,EOMONTH(BM$1,-1)+1)+1) -> 31 | BN15: =ROUND(IF($Z15="",$T15,$Z15)*(BM15/IF($W15="",$Q15,$W15)),2) -> 6644.66 | BO15: =+ROUND(BN15*0.1,2) -> 664.47 | BP15: =+SUM(BN15:BO15) -> 7309.13 | BR15: =MAX(0,MIN(IF($Y15<>"",$Y15,$S15),BR$1)-MAX($R15,EOMONTH(BR$1,-1)+1)+1) -> 30 | BS15: =ROUND(IF($Z15="",$T15,$Z15)*(BR15/IF($W15="",$Q15,$W15)),2) -> 6430.31 | BT15: =+ROUND(BS15*0.1,2) -> 643.03 | BU15: =+SUM(BS15:BT15) -> 7073.34 | BW15: =MAX(0,MIN(IF($Y15<>"",$Y15,$S15),BW$1)-MAX($R15,EOMONTH(BW$1,-1)+1)+1) -> 31 | BX15: =ROUND(IF($Z15="",$T15,$Z15)*(BW15/IF($W15="",$Q15,$W15)),2) -> 6644.66 | BY15: =+ROUND(BX15*0.1,2) -> 664.47 | BZ15: =+SUM(BX15:BY15) -> 7309.13 | CA15: =+AD15+AI15+AN15+AS15+AX15+BC15+BH15+BM15+BR15+BW15 -> 198 | CB15: =+AE15+AJ15+AO15+AT15+AY15+BD15+BI15+BN15+BS15+BX15 -> 42440.07 | CC15: =+AF15+AK15+AP15+AU15+AZ15+BE15+BJ15+BO15+BT15+BY15 -> 4244.02 | CD15: =+SUM(CB15:CC15) -> 46684.09 | CE15: =ROUND(IF($Y15<>"",$Z15,$T15)-CB15,2) -> 0 | CF15: =ROUND(IF($Y15<>"",$AA15,$U15)-CC15,2) -> -0.01 | CG15: IVP GENERAL SANCHEZ CERRO | CH15: Miler Barrientos Ramos | CI15: Gerente | CJ15: 959 090 019 | CK15: Miler Barrientos Ramos | CL15: Memorando N° 0195-2026/MPGSC/GM/AFPT | CM15: 46112 | CN15: 959 090 019
A16: 15 | B16: 48 | C16: MOQUEGUA | D16: GENERAL SANCHEZ CERRO | E16: LA CAPILLA | F16: MO-512 | G16: TOHATA (KM 9+671) - COALAQUE - SOJAMURE - CAIMAN - HEMBRUNA (KM 16+019) , HEMBRUNA (KM 16+143) - CHALLAHUAYO - TALA - CURUYO - (KM 21+465), LA CAPILLA (KM 21+579) - VINOMORE - SAHUANAY (KM 24+785) | H16: 14.876 | I16: AFIRMADO | J16: 735 | K16: 240 | L16: 87471 | M16: 8746 | N16: 96217 | O16: C_388-2026 | P16: N & S INGENIERIA Y CONSTRUCCION S.A.C. | Q16: =+$K16 -> 240 | R16: 46190 | S16: =IF(Q16+R16=0,"",Q16+R16-1) -> 46429 | T16: 83097.45 | U16: =+ROUND(T16*0.1,2) -> 8309.75 | V16: =+SUM(T16:U16) -> 91407.2 | W16: 198 | X16: =+$R16 -> 46190 | Y16: =IF(W16>0,X16+W16-1,"") -> 46387 | Z16: 68555.39 | AA16: =+ROUND(Z16*0.1,2) -> 6855.54 | AB16: =+SUM(Z16:AA16) -> 75410.93 | AD16: =MAX(0,MIN(IF($Y16<>"",$Y16,$S16),AD$1)-MAX($R16,EOMONTH(AD$1,-1)+1)+1) -> 0 | AE16: =ROUND(IF($Z16="",$T16,$Z16)*(AD16/IF($W16="",$Q16,$W16)),2) -> 0 | AF16: =+ROUND(AE16*0.1,2) -> 0 | AG16: =+SUM(AE16:AF16) -> 0 | AI16: =MAX(0,MIN(IF($Y16<>"",$Y16,$S16),AI$1)-MAX($R16,EOMONTH(AI$1,-1)+1)+1) -> 0 | AJ16: =ROUND(IF($Z16="",$T16,$Z16)*(AI16/IF($W16="",$Q16,$W16)),2) -> 0 | AK16: =+ROUND(AJ16*0.1,2) -> 0 | AL16: =+SUM(AJ16:AK16) -> 0 | AN16: =MAX(0,MIN(IF($Y16<>"",$Y16,$S16),AN$1)-MAX($R16,EOMONTH(AN$1,-1)+1)+1) -> 0 | AO16: =ROUND(IF($Z16="",$T16,$Z16)*(AN16/IF($W16="",$Q16,$W16)),2) -> 0 | AP16: =+ROUND(AO16*0.1,2) -> 0 | AQ16: =+SUM(AO16:AP16) -> 0 | AS16: =MAX(0,MIN(IF($Y16<>"",$Y16,$S16),AS$1)-MAX($R16,EOMONTH(AS$1,-1)+1)+1) -> 14 | AT16: =ROUND(IF($Z16="",$T16,$Z16)*(AS16/IF($W16="",$Q16,$W16)),2) -> 4847.35 | AU16: =+ROUND(AT16*0.1,2) -> 484.74 | AV16: =+SUM(AT16:AU16) -> 5332.09 | AX16: =MAX(0,MIN(IF($Y16<>"",$Y16,$S16),AX$1)-MAX($R16,EOMONTH(AX$1,-1)+1)+1) -> 31 | AY16: =ROUND(IF($Z16="",$T16,$Z16)*(AX16/IF($W16="",$Q16,$W16)),2) -> 10733.42 | AZ16: =+ROUND(AY16*0.1,2) -> 1073.34 | BA16: =+SUM(AY16:AZ16) -> 11806.76 | BC16: =MAX(0,MIN(IF($Y16<>"",$Y16,$S16),BC$1)-MAX($R16,EOMONTH(BC$1,-1)+1)+1) -> 31 | BD16: =ROUND(IF($Z16="",$T16,$Z16)*(BC16/IF($W16="",$Q16,$W16)),2) -> 10733.42 | BE16: =+ROUND(BD16*0.1,2) -> 1073.34 | BF16: =+SUM(BD16:BE16) -> 11806.76 | BH16: =MAX(0,MIN(IF($Y16<>"",$Y16,$S16),BH$1)-MAX($R16,EOMONTH(BH$1,-1)+1)+1) -> 30 | BI16: =ROUND(IF($Z16="",$T16,$Z16)*(BH16/IF($W16="",$Q16,$W16)),2) -> 10387.18 | BJ16: =+ROUND(BI16*0.1,2) -> 1038.72 | BK16: =+SUM(BI16:BJ16) -> 11425.9 | BM16: =MAX(0,MIN(IF($Y16<>"",$Y16,$S16),BM$1)-MAX($R16,EOMONTH(BM$1,-1)+1)+1) -> 31 | BN16: =ROUND(IF($Z16="",$T16,$Z16)*(BM16/IF($W16="",$Q16,$W16)),2) -> 10733.42 | BO16: =+ROUND(BN16*0.1,2) -> 1073.34 | BP16: =+SUM(BN16:BO16) -> 11806.76 | BR16: =MAX(0,MIN(IF($Y16<>"",$Y16,$S16),BR$1)-MAX($R16,EOMONTH(BR$1,-1)+1)+1) -> 30 | BS16: =ROUND(IF($Z16="",$T16,$Z16)*(BR16/IF($W16="",$Q16,$W16)),2) -> 10387.18 | BT16: =+ROUND(BS16*0.1,2) -> 1038.72 | BU16: =+SUM(BS16:BT16) -> 11425.9 | BW16: =MAX(0,MIN(IF($Y16<>"",$Y16,$S16),BW$1)-MAX($R16,EOMONTH(BW$1,-1)+1)+1) -> 31 | BX16: =ROUND(IF($Z16="",$T16,$Z16)*(BW16/IF($W16="",$Q16,$W16)),2) -> 10733.42 | BY16: =+ROUND(BX16*0.1,2) -> 1073.34 | BZ16: =+SUM(BX16:BY16) -> 11806.76 | CA16: =+AD16+AI16+AN16+AS16+AX16+BC16+BH16+BM16+BR16+BW16 -> 198 | CB16: =+AE16+AJ16+AO16+AT16+AY16+BD16+BI16+BN16+BS16+BX16 -> 68555.39 | CC16: =+AF16+AK16+AP16+AU16+AZ16+BE16+BJ16+BO16+BT16+BY16 -> 6855.54 | CD16: =+SUM(CB16:CC16) -> 75410.93 | CE16: =ROUND(IF($Y16<>"",$Z16,$T16)-CB16,2) -> 0 | CF16: =ROUND(IF($Y16<>"",$AA16,$U16)-CC16,2) -> 0 | CG16: IVP GENERAL SANCHEZ CERRO | CH16: Miler Barrientos Ramos | CI16: Gerente | CJ16: 959 090 019 | CK16: Miler Barrientos Ramos | CL16: Memorando N° 0195-2026/MPGSC/GM/AFPT | CM16: 46112 | CN16: 959 090 019
A17: 16 | B17: 48 | C17: MOQUEGUA | D17: GENERAL SANCHEZ CERRO | E17: UBINAS | F17: MO-529 | G17: EMP. MO-100 - SANCAYA - C.P. SACOHAYA (KM 03+480), C.P. SACOHAYA (KM 03+675) - EMP. MO-101 (KM 12+865) | H17: 12.67 | I17: AFIRMADO | J17: 735 | K17: 240 | L17: 74500 | M17: 7449 | N17: 81949 | O17: C_390-2026 | P17: N & S INGENIERIA Y CONSTRUCCION S.A.C. | Q17: =+$K17 -> 240 | R17: 46190 | S17: =IF(Q17+R17=0,"",Q17+R17-1) -> 46429 | T17: 70775 | U17: =+ROUND(T17*0.1,2) -> 7077.5 | V17: =+SUM(T17:U17) -> 77852.5 | W17: 198 | X17: =+$R17 -> 46190 | Y17: =IF(W17>0,X17+W17-1,"") -> 46387 | Z17: 58389.95 | AA17: =+ROUND(Z17*0.1,2) -> 5839 | AB17: =+SUM(Z17:AA17) -> 64228.95 | AD17: =MAX(0,MIN(IF($Y17<>"",$Y17,$S17),AD$1)-MAX($R17,EOMONTH(AD$1,-1)+1)+1) -> 0 | AE17: =ROUND(IF($Z17="",$T17,$Z17)*(AD17/IF($W17="",$Q17,$W17)),2) -> 0 | AF17: =+ROUND(AE17*0.1,2) -> 0 | AG17: =+SUM(AE17:AF17) -> 0 | AI17: =MAX(0,MIN(IF($Y17<>"",$Y17,$S17),AI$1)-MAX($R17,EOMONTH(AI$1,-1)+1)+1) -> 0 | AJ17: =ROUND(IF($Z17="",$T17,$Z17)*(AI17/IF($W17="",$Q17,$W17)),2) -> 0 | AK17: =+ROUND(AJ17*0.1,2) -> 0 | AL17: =+SUM(AJ17:AK17) -> 0 | AN17: =MAX(0,MIN(IF($Y17<>"",$Y17,$S17),AN$1)-MAX($R17,EOMONTH(AN$1,-1)+1)+1) -> 0 | AO17: =ROUND(IF($Z17="",$T17,$Z17)*(AN17/IF($W17="",$Q17,$W17)),2) -> 0 | AP17: =+ROUND(AO17*0.1,2) -> 0 | AQ17: =+SUM(AO17:AP17) -> 0 | AS17: =MAX(0,MIN(IF($Y17<>"",$Y17,$S17),AS$1)-MAX($R17,EOMONTH(AS$1,-1)+1)+1) -> 14 | AT17: =ROUND(IF($Z17="",$T17,$Z17)*(AS17/IF($W17="",$Q17,$W17)),2) -> 4128.58 | AU17: =+ROUND(AT17*0.1,2) -> 412.86 | AV17: =+SUM(AT17:AU17) -> 4541.44 | AX17: =MAX(0,MIN(IF($Y17<>"",$Y17,$S17),AX$1)-MAX($R17,EOMONTH(AX$1,-1)+1)+1) -> 31 | AY17: =ROUND(IF($Z17="",$T17,$Z17)*(AX17/IF($W17="",$Q17,$W17)),2) -> 9141.86 | AZ17: =+ROUND(AY17*0.1,2) -> 914.19 | BA17: =+SUM(AY17:AZ17) -> 10056.05 | BC17: =MAX(0,MIN(IF($Y17<>"",$Y17,$S17),BC$1)-MAX($R17,EOMONTH(BC$1,-1)+1)+1) -> 31 | BD17: =ROUND(IF($Z17="",$T17,$Z17)*(BC17/IF($W17="",$Q17,$W17)),2) -> 9141.86 | BE17: =+ROUND(BD17*0.1,2) -> 914.19 | BF17: =+SUM(BD17:BE17) -> 10056.05 | BH17: =MAX(0,MIN(IF($Y17<>"",$Y17,$S17),BH$1)-MAX($R17,EOMONTH(BH$1,-1)+1)+1) -> 30 | BI17: =ROUND(IF($Z17="",$T17,$Z17)*(BH17/IF($W17="",$Q17,$W17)),2) -> 8846.96 | BJ17: =+ROUND(BI17*0.1,2) -> 884.7 | BK17: =+SUM(BI17:BJ17) -> 9731.66 | BM17: =MAX(0,MIN(IF($Y17<>"",$Y17,$S17),BM$1)-MAX($R17,EOMONTH(BM$1,-1)+1)+1) -> 31 | BN17: =ROUND(IF($Z17="",$T17,$Z17)*(BM17/IF($W17="",$Q17,$W17)),2) -> 9141.86 | BO17: =+ROUND(BN17*0.1,2) -> 914.19 | BP17: =+SUM(BN17:BO17) -> 10056.05 | BR17: =MAX(0,MIN(IF($Y17<>"",$Y17,$S17),BR$1)-MAX($R17,EOMONTH(BR$1,-1)+1)+1) -> 30 | BS17: =ROUND(IF($Z17="",$T17,$Z17)*(BR17/IF($W17="",$Q17,$W17)),2) -> 8846.96 | BT17: =+ROUND(BS17*0.1,2) -> 884.7 | BU17: =+SUM(BS17:BT17) -> 9731.66 | BW17: =MAX(0,MIN(IF($Y17<>"",$Y17,$S17),BW$1)-MAX($R17,EOMONTH(BW$1,-1)+1)+1) -> 31 | BX17: =ROUND(IF($Z17="",$T17,$Z17)*(BW17/IF($W17="",$Q17,$W17)),2) -> 9141.86 | BY17: =+ROUND(BX17*0.1,2) -> 914.19 | BZ17: =+SUM(BX17:BY17) -> 10056.05 | CA17: =+AD17+AI17+AN17+AS17+AX17+BC17+BH17+BM17+BR17+BW17 -> 198 | CB17: =+AE17+AJ17+AO17+AT17+AY17+BD17+BI17+BN17+BS17+BX17 -> 58389.94 | CC17: =+AF17+AK17+AP17+AU17+AZ17+BE17+BJ17+BO17+BT17+BY17 -> 5839.02 | CD17: =+SUM(CB17:CC17) -> 64228.96 | CE17: =ROUND(IF($Y17<>"",$Z17,$T17)-CB17,2) -> 0.01 | CF17: =ROUND(IF($Y17<>"",$AA17,$U17)-CC17,2) -> -0.02 | CG17: IVP GENERAL SANCHEZ CERRO | CH17: Miler Barrientos Ramos | CI17: Gerente | CJ17: 959 090 019 | CK17: Miler Barrientos Ramos | CL17: Memorando N° 0195-2026/MPGSC/GM/AFPT | CM17: 46112 | CN17: 959 090 019
A18: 17 | B18: 48 | C18: MOQUEGUA | D18: GENERAL SANCHEZ CERRO | E18: UBINAS | F18: R180238 | G18: EMP. MO-101 - EMP. MO-529 | H18: 6.516 | I18: AFIRMADO | J18: 735 | K18: 240 | L18: 38314 | M18: 3831 | N18: 42145 | O18: OS-172 | P18: ASOCIACIÓN CIVIL SAGRADO CORAZÓN DE JESÚS-OMATE - ASSACOJE | Q18: =+$K18 -> 240 | R18: 46101 | S18: =IF(Q18+R18=0,"",Q18+R18-1) -> 46340 | T18: 36700 | U18: =+ROUND(T18*0.1,2) -> 3670 | V18: =+SUM(T18:U18) -> 40370 | X18: =+$R18 -> 46101 | Y18: =IF(W18>0,X18+W18-1,"") | AA18: =+ROUND(Z18*0.1,2) -> 0 | AB18: =+SUM(Z18:AA18) -> 0 | AD18: =MAX(0,MIN(IF($Y18<>"",$Y18,$S18),AD$1)-MAX($R18,EOMONTH(AD$1,-1)+1)+1) -> 12 | AE18: =ROUND(IF($Z18="",$T18,$Z18)*(AD18/IF($W18="",$Q18,$W18)),2) -> 1835 | AF18: =+ROUND(AE18*0.1,2) -> 183.5 | AG18: =+SUM(AE18:AF18) -> 2018.5 | AI18: =MAX(0,MIN(IF($Y18<>"",$Y18,$S18),AI$1)-MAX($R18,EOMONTH(AI$1,-1)+1)+1) -> 30 | AJ18: =ROUND(IF($Z18="",$T18,$Z18)*(AI18/IF($W18="",$Q18,$W18)),2) -> 4587.5 | AK18: =+ROUND(AJ18*0.1,2) -> 458.75 | AL18: =+SUM(AJ18:AK18) -> 5046.25 | AN18: =MAX(0,MIN(IF($Y18<>"",$Y18,$S18),AN$1)-MAX($R18,EOMONTH(AN$1,-1)+1)+1) -> 31 | AO18: =ROUND(IF($Z18="",$T18,$Z18)*(AN18/IF($W18="",$Q18,$W18)),2) -> 4740.42 | AP18: =+ROUND(AO18*0.1,2) -> 474.04 | AQ18: =+SUM(AO18:AP18) -> 5214.46 | AS18: =MAX(0,MIN(IF($Y18<>"",$Y18,$S18),AS$1)-MAX($R18,EOMONTH(AS$1,-1)+1)+1) -> 30 | AT18: =ROUND(IF($Z18="",$T18,$Z18)*(AS18/IF($W18="",$Q18,$W18)),2) -> 4587.5 | AU18: =+ROUND(AT18*0.1,2) -> 458.75 | AV18: =+SUM(AT18:AU18) -> 5046.25 | AX18: =MAX(0,MIN(IF($Y18<>"",$Y18,$S18),AX$1)-MAX($R18,EOMONTH(AX$1,-1)+1)+1) -> 31 | AY18: =ROUND(IF($Z18="",$T18,$Z18)*(AX18/IF($W18="",$Q18,$W18)),2) -> 4740.42 | AZ18: =+ROUND(AY18*0.1,2) -> 474.04 | BA18: =+SUM(AY18:AZ18) -> 5214.46 | BC18: =MAX(0,MIN(IF($Y18<>"",$Y18,$S18),BC$1)-MAX($R18,EOMONTH(BC$1,-1)+1)+1) -> 31 | BD18: =ROUND(IF($Z18="",$T18,$Z18)*(BC18/IF($W18="",$Q18,$W18)),2) -> 4740.42 | BE18: =+ROUND(BD18*0.1,2) -> 474.04 | BF18: =+SUM(BD18:BE18) -> 5214.46 | BH18: =MAX(0,MIN(IF($Y18<>"",$Y18,$S18),BH$1)-MAX($R18,EOMONTH(BH$1,-1)+1)+1) -> 30 | BI18: =ROUND(IF($Z18="",$T18,$Z18)*(BH18/IF($W18="",$Q18,$W18)),2) -> 4587.5 | BJ18: =+ROUND(BI18*0.1,2) -> 458.75 | BK18: =+SUM(BI18:BJ18) -> 5046.25 | BM18: =MAX(0,MIN(IF($Y18<>"",$Y18,$S18),BM$1)-MAX($R18,EOMONTH(BM$1,-1)+1)+1) -> 31 | BN18: =ROUND(IF($Z18="",$T18,$Z18)*(BM18/IF($W18="",$Q18,$W18)),2) -> 4740.42 | BO18: =+ROUND(BN18*0.1,2) -> 474.04 | BP18: =+SUM(BN18:BO18) -> 5214.46 | BR18: =MAX(0,MIN(IF($Y18<>"",$Y18,$S18),BR$1)-MAX($R18,EOMONTH(BR$1,-1)+1)+1) -> 14 | BS18: =ROUND(IF($Z18="",$T18,$Z18)*(BR18/IF($W18="",$Q18,$W18)),2) -> 2140.83 | BT18: =+ROUND(BS18*0.1,2) -> 214.08 | BU18: =+SUM(BS18:BT18) -> 2354.91 | BW18: =MAX(0,MIN(IF($Y18<>"",$Y18,$S18),BW$1)-MAX($R18,EOMONTH(BW$1,-1)+1)+1) -> 0 | BX18: =ROUND(IF($Z18="",$T18,$Z18)*(BW18/IF($W18="",$Q18,$W18)),2) -> 0 | BY18: =+ROUND(BX18*0.1,2) -> 0 | BZ18: =+SUM(BX18:BY18) -> 0 | CA18: =+AD18+AI18+AN18+AS18+AX18+BC18+BH18+BM18+BR18+BW18 -> 240 | CB18: =+AE18+AJ18+AO18+AT18+AY18+BD18+BI18+BN18+BS18+BX18 -> 36700.01 | CC18: =+AF18+AK18+AP18+AU18+AZ18+BE18+BJ18+BO18+BT18+BY18 -> 3669.99 | CD18: =+SUM(CB18:CC18) -> 40370 | CE18: =ROUND(IF($Y18<>"",$Z18,$T18)-CB18,2) -> -0.01 | CF18: =ROUND(IF($Y18<>"",$AA18,$U18)-CC18,2) -> 0.01 | CG18: IVP GENERAL SANCHEZ CERRO | CH18: Miler Barrientos Ramos | CI18: Gerente | CJ18: 959 090 019 | CK18: Miler Barrientos Ramos | CL18: Memorando N° 0195-2026/MPGSC/GM/AFPT | CM18: 46112 | CN18: 959 090 019
